Workbook

Sheet Executive-Summary
B2: ASTRAL SCHOOL — Executive Summary
B3: Nagre Nagar | Excelerate Learning Foundation | 6-Year Financial Overview
B6: Revenue CAGR | D6: Cumulative Net Income | F6: Payback Period | H6: Student Growth
B7: =('Financial-Summary'!E11/'Financial-Summary'!E6)^(1/5)-1 -> 0.27337726 | D7: =SUM('Financial-Summary'!M6:'Financial-Summary'!M11) -> 8890220.9 | F7: Year 3 | H7: =('Financial-Summary'!C11/'Financial-Summary'!C6)-1 -> 1.7
B8: 5-Year Compound Annual | D8: 6-Year Total (₹) | F8: Cumulative Breakeven | H8: 200 → 540 Students
B10: Year-by-Year Performance
B11: Year | C11: Students | D11: Revenue | E11: Total Expenses | F11: Net Income | G11: Margin % | H11: Cumulative Income | I11: YoY Revenue Growth
B12: ='Financial-Summary'!B6 -> THIS | C12: ='Financial-Summary'!C6 -> 200 | D12: ='Financial-Summary'!E6 -> 7500000 | E12: ='Financial-Summary'!L6 -> 8748000 | F12: ='Financial-Summary'!M6 -> -1248000 | G12: ='Financial-Summary'!M6/'Financial-Summary'!E6 -> -0.1664 | H12: =F12 -> -1248000 | I12: —
B13: ='Financial-Summary'!B7 -> 2027-28 | C13: ='Financial-Summary'!C7 -> 250 | D13: ='Financial-Summary'!E7 -> 9150862.1 | E13: ='Financial-Summary'!L7 -> 9797000 | F13: ='Financial-Summary'!M7 -> -646137.93 | G13: ='Financial-Summary'!M7/'Financial-Summary'!E7 -> -0.070609515 | H13: =H12+F13 -> -1894137.9 | I13: =(D13-D12)/D12 -> 0.22011494
B14: ='Financial-Summary'!B8 -> 2028-29 | C14: ='Financial-Summary'!C8 -> 310 | D14: ='Financial-Summary'!E8 -> 12568286 | E14: ='Financial-Summary'!L8 -> 10633750 | F14: ='Financial-Summary'!M8 -> 1934535.7 | G14: ='Financial-Summary'!M8/'Financial-Summary'!E8 -> 0.153922 | H14: =H13+F14 -> 40397.783 | I14: =(D14-D13)/D13 -> 0.37345374
B15: ='Financial-Summary'!B9 -> 2029-30 | C15: ='Financial-Summary'!C9 -> 370 | D15: ='Financial-Summary'!E9 -> 15188049 | E15: ='Financial-Summary'!L9 -> 12392512 | F15: ='Financial-Summary'!M9 -> 2795536.3 | G15: ='Financial-Summary'!M9/'Financial-Summary'!E9 -> 0.18406158 | H15: =H14+F15 -> 2835934.1 | I15: =(D15-D14)/D14 -> 0.20844235
B16: ='Financial-Summary'!B10 -> 2030-31 | C16: ='Financial-Summary'!C10 -> 460 | D16: ='Financial-Summary'!E10 -> 20148000 | E16: ='Financial-Summary'!L10 -> 17448149 | F16: ='Financial-Summary'!M10 -> 2699850.6 | G16: ='Financial-Summary'!M10/'Financial-Summary'!E10 -> 0.13400092 | H16: =H15+F16 -> 5535784.7 | I16: =(D16-D15)/D15 -> 0.32656935
B17: ='Financial-Summary'!B11 -> 2031-32 | C17: ='Financial-Summary'!C11 -> 540 | D17: ='Financial-Summary'!E11 -> 25110000 | E17: ='Financial-Summary'!L11 -> 21755564 | F17: ='Financial-Summary'!M11 -> 3354436.2 | G17: ='Financial-Summary'!M11/'Financial-Summary'!E11 -> 0.13358965 | H17: =H16+F17 -> 8890220.9 | I17: =(D17-D16)/D16 -> 0.24627755

Sheet Investor-Returns
B2: Investor Return Scenarios
B3: Based on 15% equity stake | ~₹11.67 Lacs per 1% equity | ₹1.75 Cr total raise
B6: Deal Structure
B8: Equity Offered | D8: 0.15
B9: Total Investment | D9: 17500000 | E9: (₹)
B10: Price per 1% Equity | D10: =D9/(D8*100) -> 1166666.7 | E10: (₹ per 1%)
B11: Implied Pre-Money Valuation | D11: =D9/D8-D9 -> 99166667 | E11: (₹)
B12: Implied Post-Money Valuation | D12: =D11+D9 -> 1.1666667e+08 | E12: (₹)
B14: Investor Return by Year
B16: Year | C16: Revenue | D16: Net Income | E16: Investor Share of Income | F16: Cumulative Investor Income | G16: ROI on Investment | H16: Investor Multiple
B17: ='Executive-Summary'!B12 -> THIS | C17: ='Executive-Summary'!D12 -> 7500000 | D17: ='Executive-Summary'!F12 -> -1248000 | E17: =D17*$D$8 -> -187200 | F17: =E17 -> -187200 | G17: =F17/$D$9 -> -0.010697143 | H17: =(F17+$D$9)/$D$9 -> 0.98930286
B18: ='Executive-Summary'!B13 -> 2027-28 | C18: ='Executive-Summary'!D13 -> 9150862.1 | D18: ='Executive-Summary'!F13 -> -646137.93 | E18: =D18*$D$8 -> -96920.69 | F18: =F17+E18 -> -284120.69 | G18: =F18/$D$9 -> -0.016235468 | H18: =(F18+$D$9)/$D$9 -> 0.98376453
B19: ='Executive-Summary'!B14 -> 2028-29 | C19: ='Executive-Summary'!D14 -> 12568286 | D19: ='Executive-Summary'!F14 -> 1934535.7 | E19: =D19*$D$8 -> 290180.36 | F19: =F18+E19 -> 6059.6675 | G19: =F19/$D$9 -> 0.00034626671 | H19: =(F19+$D$9)/$D$9 -> 1.0003463
B20: ='Executive-Summary'!B15 -> 2029-30 | C20: ='Executive-Summary'!D15 -> 15188049 | D20: ='Executive-Summary'!F15 -> 2795536.3 | E20: =D20*$D$8 -> 419330.44 | F20: =F19+E20 -> 425390.11 | G20: =F20/$D$9 -> 0.024308006 | H20: =(F20+$D$9)/$D$9 -> 1.024308
B21: ='Executive-Summary'!B16 -> 2030-31 | C21: ='Executive-Summary'!D16 -> 20148000 | D21: ='Executive-Summary'!F16 -> 2699850.6 | E21: =D21*$D$8 -> 404977.59 | F21: =F20+E21 -> 830367.7 | G21: =F21/$D$9 -> 0.047449583 | H21: =(F21+$D$9)/$D$9 -> 1.0474496
B22: ='Executive-Summary'!B17 -> 2031-32 | C22: ='Executive-Summary'!D17 -> 25110000 | D22: ='Executive-Summary'!F17 -> 3354436.2 | E22: =D22*$D$8 -> 503165.43 | F22: =F21+E22 -> 1333533.1 | G22: =F22/$D$9 -> 0.076201893 | H22: =(F22+$D$9)/$D$9 -> 1.0762019
B25: Exit Valuation Scenarios (Year 6 — 2031-32)
B26: Investor exit value = 15% × School Valuation at exit
B28: Valuation Method | C28: Revenue Multiple | D28: School Valuation | E28: Investor Exit Value | F28: Total Return (Exit + Income) | G28: ROI | H28: MOIC
B29: Conservative | C29: 2 | D29: =C29*'Executive-Summary'!D17 -> 50220000 | E29: =D29*$D$8 -> 7533000 | F29: =E29+F22 -> 8866533.1 | G29: =(F29-$D$9)/$D$9 -> -0.49334096 | H29: =F29/$D$9 -> 0.50665904
B30: Base Case | C30: 3 | D30: =C30*'Executive-Summary'!D17 -> 75330000 | E30: =D30*$D$8 -> 11299500 | F30: =E30+F22 -> 12633033 | G30: =(F30-$D$9)/$D$9 -> -0.27811239 | H30: =F30/$D$9 -> 0.72188761
B31: Optimistic | C31: 5 | D31: =C31*'Executive-Summary'!D17 -> 125550000 | E31: =D31*$D$8 -> 18832500 | F31: =E31+F22 -> 20166033 | G31: =(F31-$D$9)/$D$9 -> 0.15234475 | H31: =F31/$D$9 -> 1.1523448

Sheet Moderate-Growth
B2: Moderate Growth Scenario
B3: ~75–120 students/year growth vs ~50–90 in conservative | Proportional expense & staff scaling
B6: Growth Assumptions
C8: 2026-27 | D8: 2027-28 | E8: 2028-29 | F8: 2029-30 | G8: 2030-31 | H8: 2031-32
B9: Conservative Students | C9: ='Financial-Summary'!C6 -> 200 | D9: ='Financial-Summary'!C7 -> 250 | E9: ='Financial-Summary'!C8 -> 310 | F9: ='Financial-Summary'!C9 -> 370 | G9: ='Financial-Summary'!C10 -> 460 | H9: ='Financial-Summary'!C11 -> 540
B10: Moderate Students | C10: 200 | D10: 275 | E10: 375 | F10: 485 | G10: 605 | H10: 705
B11: YoY Student Addition | C11: — | D11: =D10-C10 -> 75 | E11: =E10-D10 -> 100 | F11: =F10-E10 -> 110 | G11: =G10-F10 -> 120 | H11: =H10-G10 -> 100
B12: Scale Factor vs Conservative | C12: =C10/C9 -> 1 | D12: =D10/D9 -> 1.1 | E12: =E10/E9 -> 1.2096774 | F12: =F10/F9 -> 1.3108108 | G12: =G10/G9 -> 1.3152174 | H12: =H10/H9 -> 1.3055556
B14: Projected Staff (Moderate)
C16: 2026-27 | D16: 2027-28 | E16: 2028-29 | F16: 2029-30 | G16: 2030-31 | H16: 2031-32
B17: Educators | C17: =ROUNDUP('Staff-Plan'!D7*C12,0) -> 10 | D17: =ROUNDUP('Staff-Plan'!E7*D12,0) -> 13 | E17: =ROUNDUP('Staff-Plan'!F7*E12,0) -> 17 | F17: =ROUNDUP('Staff-Plan'!G7*F12,0) -> 23 | G17: =ROUNDUP('Staff-Plan'!H7*G12,0) -> 25 | H17: =ROUNDUP('Staff-Plan'!I7*H12,0) -> 28
B18: Aunties | C18: =ROUNDUP('Staff-Plan'!D8*C12,0) -> 3 | D18: =ROUNDUP('Staff-Plan'!E8*D12,0) -> 6 | E18: =ROUNDUP('Staff-Plan'!F8*E12,0) -> 8 | F18: =ROUNDUP('Staff-Plan'!G8*F12,0) -> 10 | G18: =ROUNDUP('Staff-Plan'!H8*G12,0) -> 14 | H18: =ROUNDUP('Staff-Plan'!I8*H12,0) -> 16
B19: Security Staff | C19: =ROUNDUP('Staff-Plan'!D9*C12,0) -> 2 | D19: =ROUNDUP('Staff-Plan'!E9*D12,0) -> 3 | E19: =ROUNDUP('Staff-Plan'!F9*E12,0) -> 3 | F19: =ROUNDUP('Staff-Plan'!G9*F12,0) -> 3 | G19: =ROUNDUP('Staff-Plan'!H9*G12,0) -> 4 | H19: =ROUNDUP('Staff-Plan'!I9*H12,0) -> 4
B20: Visiting Faculty | C20: =ROUNDUP('Staff-Plan'!D10*C12,0) -> 4 | D20: =ROUNDUP('Staff-Plan'!E10*D12,0) -> 5 | E20: =ROUNDUP('Staff-Plan'!F10*E12,0) -> 7 | F20: =ROUNDUP('Staff-Plan'!G10*F12,0) -> 7 | G20: =ROUNDUP('Staff-Plan'!H10*G12,0) -> 7 | H20: =ROUNDUP('Staff-Plan'!I10*H12,0) -> 10
B21: Administrative Staff | C21: =ROUNDUP('Staff-Plan'!D11*C12,0) -> 1 | D21: =ROUNDUP('Staff-Plan'!E11*D12,0) -> 2 | E21: =ROUNDUP('Staff-Plan'!F11*E12,0) -> 2 | F21: =ROUNDUP('Staff-Plan'!G11*F12,0) -> 2 | G21: =ROUNDUP('Staff-Plan'!H11*G12,0) -> 3 | H21: =ROUNDUP('Staff-Plan'!I11*H12,0) -> 3
B22: Principal & HM | C22: =ROUNDUP('Staff-Plan'!D12*C12,0) -> 0 | D22: =ROUNDUP('Staff-Plan'!E12*D12,0) -> 0 | E22: =ROUNDUP('Staff-Plan'!F12*E12,0) -> 0 | F22: =ROUNDUP('Staff-Plan'!G12*F12,0) -> 0 | G22: =ROUNDUP('Staff-Plan'!H12*G12,0) -> 2 | H22: =ROUNDUP('Staff-Plan'!I12*H12,0) -> 2
B23: Total Staff | C23: =SUM(C17:C22) -> 20 | D23: =SUM(D17:D22) -> 29 | E23: =SUM(E17:E22) -> 37 | F23: =SUM(F17:F22) -> 45 | G23: =SUM(G17:G22) -> 55 | H23: =SUM(H17:H22) -> 63
B25: Projected P&L (Moderate Growth)
C27: 2026-27 | D27: 2027-28 | E27: 2028-29 | F27: 2029-30 | G27: 2030-31 | H27: 2031-32
B28: Revenue | C28: ='Financial-Summary'!E6*C12 -> 7500000 | D28: ='Financial-Summary'!E7*D12 -> 10065948 | E28: ='Financial-Summary'!E8*E12 -> 15203571 | F28: ='Financial-Summary'!E9*F12 -> 19908659 | G28: ='Financial-Summary'!E10*G12 -> 26499000 | H28: ='Financial-Summary'!E11*H12 -> 32782500
B29: Staff Expenses | C29: ='Financial-Summary'!F6*C12 -> 2808000 | D29: ='Financial-Summary'!F7*D12 -> 4039200 | E29: ='Financial-Summary'!F8*E12 -> 5922580.6 | F29: ='Financial-Summary'!F9*F12 -> 8667081.1 | G29: ='Financial-Summary'!F10*G12 -> 12436696 | H29: ='Financial-Summary'!F11*H12 -> 15933000
B30: Rent | C30: ='Financial-Summary'!G6 -> 2040000 | D30: ='Financial-Summary'!G7 -> 2220000 | E30: ='Financial-Summary'!G8 -> 2178000 | F30: ='Financial-Summary'!G9 -> 2208000 | G30: ='Financial-Summary'!G10 -> 2539200 | H30: ='Financial-Summary'!G11 -> 2539200
B31: One-Time Expenses | C31: ='Financial-Summary'!H6 -> 0 | D31: ='Financial-Summary'!H7 -> 500000 | E31: ='Financial-Summary'!H8 -> 1000000 | F31: ='Financial-Summary'!H9 -> 600000 | G31: ='Financial-Summary'!H10 -> 2000000 | H31: ='Financial-Summary'!H11 -> 3000000
B32: In-House Events | C32: ='Financial-Summary'!I6 -> 500000 | D32: ='Financial-Summary'!I7 -> 575000 | E32: ='Financial-Summary'!I8 -> 661250 | F32: ='Financial-Summary'!I9 -> 760437.5 | G32: ='Financial-Summary'!I10 -> 874503.12 | H32: ='Financial-Summary'!I11 -> 1005678.6
B33: Mktng+Legal+Emergency | C33: ='Financial-Summary'!J6 -> 1000000 | D33: ='Financial-Summary'!J7 -> 1150000 | E33: ='Financial-Summary'!J8 -> 1322500 | F33: ='Financial-Summary'!J9 -> 1520875 | G33: ='Financial-Summary'!J10 -> 1749006.2 | H33: ='Financial-Summary'!J11 -> 2011357.2
B34: Other Expenses | C34: ='Financial-Summary'!K6 -> 400000 | D34: ='Financial-Summary'!K7 -> 480000 | E34: ='Financial-Summary'!K8 -> 576000 | F34: ='Financial-Summary'!K9 -> 691200 | G34: ='Financial-Summary'!K10 -> 829440 | H34: ='Financial-Summary'!K11 -> 995328
B35: Total Expenses | C35: =SUM(C29:C34) -> 6748000 | D35: =SUM(D29:D34) -> 8964200 | E35: =SUM(E29:E34) -> 11660331 | F35: =SUM(F29:F34) -> 14447594 | G35: =SUM(G29:G34) -> 20428845 | H35: =SUM(H29:H34) -> 25484564
B36: Net Income | C36: =C28-C35 -> 752000 | D36: =D28-D35 -> 1101748.3 | E36: =E28-E35 -> 3543240.8 | F36: =F28-F35 -> 5461065 | G36: =G28-G35 -> 6070155 | H36: =H28-H35 -> 7297936.2
B37: Net Margin % | C37: =C36/C28 -> 0.10026667 | D37: =D36/D28 -> 0.109453 | E37: =E36/E28 -> 0.23305319 | F37: =F36/F28 -> 0.27430602 | G37: =G36/G28 -> 0.2290711 | H37: =H36/H28 -> 0.22261683
B39: Net Income Comparison
C41: 2026-27 | D41: 2027-28 | E41: 2028-29 | F41: 2029-30 | G41: 2030-31 | H41: 2031-32
B42: Conservative Net Income | C42: ='Financial-Summary'!M6 -> -1248000 | D42: ='Financial-Summary'!M7 -> -646137.93 | E42: ='Financial-Summary'!M8 -> 1934535.7 | F42: ='Financial-Summary'!M9 -> 2795536.3 | G42: ='Financial-Summary'!M10 -> 2699850.6 | H42: ='Financial-Summary'!M11 -> 3354436.2
B43: Moderate Net Income | C43: =C36 -> 752000 | D43: =D36 -> 1101748.3 | E43: =E36 -> 3543240.8 | F43: =F36 -> 5461065 | G43: =G36 -> 6070155 | H43: =H36 -> 7297936.2
B44: Upside (₹) | C44: =C43-C42 -> 2000000 | D44: =D43-D42 -> 1747886.2 | E44: =E43-E42 -> 1608705.1 | F44: =F43-F42 -> 2665528.7 | G44: =G43-G42 -> 3370304.3 | H44: =H43-H42 -> 3943500

Sheet Sports-Complex
B2: Sports Complex — Revenue Model
B3: 10,000+ sq ft | Turf, Courts, Indoor Hall | School + Commercial Use
B6: Facility & Pricing Assumptions
C7: 2026-27 | D7: 2027-28 | E7: 2028-29 | F7: 2029-30 | G7: 2030-31 | H7: 2031-32
B8: Turf — Hourly Rate (₹) | C8: 800 | D8: =C8*1.1 -> 880 | E8: =D8*1.1 -> 968 | F8: =E8*1.15 -> 1113.2 | G8: =F8*1.15 -> 1280.18 | H8: =G8*1.1 -> 1408.198
B9: Badminton Court — Hourly Rate (₹) | C9: 0 | D9: 500 | E9: =D9*1.1 -> 550 | F9: =E9*1.15 -> 632.5 | G9: =F9*1.15 -> 727.375 | H9: =G9*1.1 -> 800.1125
B10: Rental Hours/Day (7–10 PM) | C10: 3 | D10: 3 | E10: 3 | F10: 3 | G10: 3 | H10: 3
B11: Operating Days/Month | C11: 26 | D11: 26 | E11: 28 | F11: 28 | G11: 30 | H11: 30
B12: Occupancy Rate | C12: 0.25 | D12: 0.4 | E12: 0.55 | F12: 0.65 | G12: 0.75 | H12: 0.85
B14: Revenue Streams
C16: 2026-27 | D16: 2027-28 | E16: 2028-29 | F16: 2029-30 | G16: 2030-31 | H16: 2031-32
B17: Turf Rentals | C17: =C8*C10*C11*12*C12 -> 187200 | D17: =D8*D10*D11*12*D12 -> 329472 | E17: =E8*E10*E11*12*E12 -> 536659.2 | F17: =F8*F10*F11*12*F12 -> 729368.64 | G17: =G8*G10*G11*12*G12 -> 1036945.8 | H17: =H8*H10*H11*12*H12 -> 1292725.8
B18: Court Rentals (added Year 2) | C18: 0 | D18: =D9*2*D10*D11*12*D12 -> 374400 | E18: =E9*2*E10*E11*12*E12 -> 609840 | F18: =F9*2*F10*F11*12*F12 -> 828828 | G18: =G9*2*G10*G11*12*G12 -> 1178347.5 | H18: =H9*2*H10*H11*12*H12 -> 1469006.6
B19: Coaching Students | C19: 20 | D19: 50 | E19: 90 | F19: 140 | G19: 200 | H19: 280
B20: Monthly Fee (₹) | C20: 1000 | D20: 1200 | E20: 1500 | F20: 1800 | G20: 2000 | H20: 2500
B21: Coaching Academy (4–7 PM) | C21: =C19*C20*12 -> 240000 | D21: =D19*D20*12 -> 720000 | E21: =E19*E20*12 -> 1620000 | F21: =F19*F20*12 -> 3024000 | G21: =G19*G20*12 -> 4800000 | H21: =H19*H20*12 -> 8400000
B22: Tournaments & Events | C22: 0 | D22: 100000 | E22: 300000 | F22: 500000 | G22: 800000 | H22: 1200000
B23: Corporate & Private Bookings | C23: 0 | D23: 50000 | E23: 150000 | F23: 300000 | G23: 500000 | H23: 800000
B24: Total Sports Revenue | C24: =SUM(C17:C23) -> 428220 | D24: =SUM(D17:D23) -> 1575122 | E24: =SUM(E17:E23) -> 3218089.2 | F24: =SUM(F17:F23) -> 5384136.6 | G24: =SUM(G17:G23) -> 8317493.3 | H24: =SUM(H17:H23) -> 13164512
B26: Operating Costs
C28: 2026-27 | D28: 2027-28 | E28: 2028-29 | F28: 2029-30 | G28: 2030-31 | H28: 2031-32
B29: Turf/Court Maintenance | C29: 100000 | D29: 120000 | E29: 150000 | F29: 180000 | G29: 200000 | H29: 250000
B30: Sports Staff & Coaches (3→8) | C30: 360000 | D30: 600000 | E30: 900000 | F30: 1200000 | G30: 1500000 | H30: 1920000
B31: Utilities & Insurance | C31: 60000 | D31: 80000 | E31: 100000 | F31: 120000 | G31: 150000 | H31: 180000
B32: Marketing & Promotions | C32: 50000 | D32: 80000 | E32: 100000 | F32: 120000 | G32: 150000 | H32: 200000
B33: Total Operating Costs | C33: =SUM(C29:C32) -> 570000 | D33: =SUM(D29:D32) -> 880000 | E33: =SUM(E29:E32) -> 1250000 | F33: =SUM(F29:F32) -> 1620000 | G33: =SUM(G29:G32) -> 2000000 | H33: =SUM(H29:H32) -> 2550000
B35: Sports Complex — Net Profit
C37: 2026-27 | D37: 2027-28 | E37: 2028-29 | F37: 2029-30 | G37: 2030-31 | H37: 2031-32 | I37: 6-Year Total
B38: Total Revenue | C38: =C24 -> 428220 | D38: =D24 -> 1575122 | E38: =E24 -> 3218089.2 | F38: =F24 -> 5384136.6 | G38: =G24 -> 8317493.3 | H38: =H24 -> 13164512 | I38: =SUM(C38:H38) -> 32087573
B39: Total Costs | C39: =C33 -> 570000 | D39: =D33 -> 880000 | E39: =E33 -> 1250000 | F39: =F33 -> 1620000 | G39: =G33 -> 2000000 | H39: =H33 -> 2550000 | I39: =SUM(C39:H39) -> 8870000
B40: Net Profit | C40: =C38-C39 -> -141780 | D40: =D38-D39 -> 695122 | E40: =E38-E39 -> 1968089.2 | F40: =F38-F39 -> 3764136.6 | G40: =G38-G39 -> 6317493.3 | H40: =H38-H39 -> 10614512 | I40: =SUM(C40:H40) -> 23217573
B41: Net Margin % | C41: =C40/C38 -> -0.3310915 | D41: =D40/D38 -> 0.44131312 | E41: =E40/E38 -> 0.61157074 | F41: =F40/F38 -> 0.69911611 | G41: =G40/G38 -> 0.75954294 | H41: =H40/H38 -> 0.80629742 | I41: =I40/I38 -> 0.723569
B42: Monthly Revenue (avg) | C42: =C38/12 -> 35685 | D42: =D38/12 -> 131260.17 | E42: =E38/12 -> 268174.1 | F42: =F38/12 -> 448678.05 | G42: =G38/12 -> 693124.44 | H42: =H38/12 -> 1097042.7
B44: ★ Monthly revenue starts at ~₹20K and scales to ₹7L+/month by Year 6
B47: Investor Returns — School + Sports Complex Combined
B48: 15% equity | ₹1.75 Cr investment | All scenarios include sports complex profit
C51: 2026-27 | D51: 2027-28 | E51: 2028-29 | F51: 2029-30 | G51: 2030-31 | H51: 2031-32 | I51: 6-Year Total
B52: School Income (Conservative) | C52: ='Financial-Summary'!M6 -> -1248000 | D52: ='Financial-Summary'!M7 -> -646137.93 | E52: ='Financial-Summary'!M8 -> 1934535.7 | F52: ='Financial-Summary'!M9 -> 2795536.3 | G52: ='Financial-Summary'!M10 -> 2699850.6 | H52: ='Financial-Summary'!M11 -> 3354436.2 | I52: =SUM(C52:H52) -> 8890220.9
B53: School Income (Moderate) | C53: ='Moderate-Growth'!C36 -> 752000 | D53: ='Moderate-Growth'!D36 -> 1101748.3 | E53: ='Moderate-Growth'!E36 -> 3543240.8 | F53: ='Moderate-Growth'!F36 -> 5461065 | G53: ='Moderate-Growth'!G36 -> 6070155 | H53: ='Moderate-Growth'!H36 -> 7297936.2 | I53: =SUM(C53:H53) -> 24226145
B54: School Income (Bullish) | C54: ='Bullish-Growth'!C36 -> 752000 | D54: ='Bullish-Growth'!D36 -> 1649634.5 | E54: ='Bullish-Growth'!E36 -> 5151945.9 | F54: ='Bullish-Growth'!F36 -> 7894808.5 | G54: ='Bullish-Growth'!G36 -> 9440459.3 | H54: ='Bullish-Growth'!H36 -> 12436436 | I54: =SUM(C54:H54) -> 37325284
...

Sheet Bullish-Growth
B2: Bullish Growth Scenario
B3: ~100–170 students/year growth | Proportional expense & staff scaling
B6: Growth Assumptions
C8: 2026-27 | D8: 2027-28 | E8: 2028-29 | F8: 2029-30 | G8: 2030-31 | H8: 2031-32
B9: Conservative Students | C9: ='Financial-Summary'!C6 -> 200 | D9: ='Financial-Summary'!C7 -> 250 | E9: ='Financial-Summary'!C8 -> 310 | F9: ='Financial-Summary'!C9 -> 370 | G9: ='Financial-Summary'!C10 -> 460 | H9: ='Financial-Summary'!C11 -> 540
B10: Bullish Students | C10: 200 | D10: 300 | E10: 440 | F10: 590 | G10: 750 | H10: 920
B11: YoY Student Addition | C11: — | D11: =D10-C10 -> 100 | E11: =E10-D10 -> 140 | F11: =F10-E10 -> 150 | G11: =G10-F10 -> 160 | H11: =H10-G10 -> 170
B12: Scale Factor vs Conservative | C12: =C10/C9 -> 1 | D12: =D10/D9 -> 1.2 | E12: =E10/E9 -> 1.4193548 | F12: =F10/F9 -> 1.5945946 | G12: =G10/G9 -> 1.6304348 | H12: =H10/H9 -> 1.7037037
B14: Projected Staff (Bullish)
C16: 2026-27 | D16: 2027-28 | E16: 2028-29 | F16: 2029-30 | G16: 2030-31 | H16: 2031-32
B17: Educators | C17: =ROUNDUP('Staff-Plan'!D7*C12,0) -> 10 | D17: =ROUNDUP('Staff-Plan'!E7*D12,0) -> 14 | E17: =ROUNDUP('Staff-Plan'!F7*E12,0) -> 20 | F17: =ROUNDUP('Staff-Plan'!G7*F12,0) -> 28 | G17: =ROUNDUP('Staff-Plan'!H7*G12,0) -> 31 | H17: =ROUNDUP('Staff-Plan'!I7*H12,0) -> 36
B18: Aunties | C18: =ROUNDUP('Staff-Plan'!D8*C12,0) -> 3 | D18: =ROUNDUP('Staff-Plan'!E8*D12,0) -> 6 | E18: =ROUNDUP('Staff-Plan'!F8*E12,0) -> 9 | F18: =ROUNDUP('Staff-Plan'!G8*F12,0) -> 12 | G18: =ROUNDUP('Staff-Plan'!H8*G12,0) -> 17 | H18: =ROUNDUP('Staff-Plan'!I8*H12,0) -> 21
B19: Security Staff | C19: =ROUNDUP('Staff-Plan'!D9*C12,0) -> 2 | D19: =ROUNDUP('Staff-Plan'!E9*D12,0) -> 3 | E19: =ROUNDUP('Staff-Plan'!F9*E12,0) -> 3 | F19: =ROUNDUP('Staff-Plan'!G9*F12,0) -> 4 | G19: =ROUNDUP('Staff-Plan'!H9*G12,0) -> 5 | H19: =ROUNDUP('Staff-Plan'!I9*H12,0) -> 6
B20: Visiting Faculty | C20: =ROUNDUP('Staff-Plan'!D10*C12,0) -> 4 | D20: =ROUNDUP('Staff-Plan'!E10*D12,0) -> 5 | E20: =ROUNDUP('Staff-Plan'!F10*E12,0) -> 8 | F20: =ROUNDUP('Staff-Plan'!G10*F12,0) -> 8 | G20: =ROUNDUP('Staff-Plan'!H10*G12,0) -> 9 | H20: =ROUNDUP('Staff-Plan'!I10*H12,0) -> 12
B21: Administrative Staff | C21: =ROUNDUP('Staff-Plan'!D11*C12,0) -> 1 | D21: =ROUNDUP('Staff-Plan'!E11*D12,0) -> 2 | E21: =ROUNDUP('Staff-Plan'!F11*E12,0) -> 2 | F21: =ROUNDUP('Staff-Plan'!G11*F12,0) -> 2 | G21: =ROUNDUP('Staff-Plan'!H11*G12,0) -> 4 | H21: =ROUNDUP('Staff-Plan'!I11*H12,0) -> 4
B22: Principal & HM | C22: =ROUNDUP('Staff-Plan'!D12*C12,0) -> 0 | D22: =ROUNDUP('Staff-Plan'!E12*D12,0) -> 0 | E22: =ROUNDUP('Staff-Plan'!F12*E12,0) -> 0 | F22: =ROUNDUP('Staff-Plan'!G12*F12,0) -> 0 | G22: =ROUNDUP('Staff-Plan'!H12*G12,0) -> 2 | H22: =ROUNDUP('Staff-Plan'!I12*H12,0) -> 2
B23: Total Staff | C23: =SUM(C17:C22) -> 20 | D23: =SUM(D17:D22) -> 30 | E23: =SUM(E17:E22) -> 42 | F23: =SUM(F17:F22) -> 54 | G23: =SUM(G17:G22) -> 68 | H23: =SUM(H17:H22) -> 81
B25: Projected P&L (Bullish Growth)
C27: 2026-27 | D27: 2027-28 | E27: 2028-29 | F27: 2029-30 | G27: 2030-31 | H27: 2031-32
B28: Revenue | C28: ='Financial-Summary'!E6*C12 -> 7500000 | D28: ='Financial-Summary'!E7*D12 -> 10981034 | E28: ='Financial-Summary'!E8*E12 -> 17838857 | F28: ='Financial-Summary'!E9*F12 -> 24218780 | G28: ='Financial-Summary'!E10*G12 -> 32850000 | H28: ='Financial-Summary'!E11*H12 -> 42780000
B29: Staff Expenses | C29: ='Financial-Summary'!F6*C12 -> 2808000 | D29: ='Financial-Summary'!F7*D12 -> 4406400 | E29: ='Financial-Summary'!F8*E12 -> 6949161.3 | F29: ='Financial-Summary'!F9*F12 -> 10543459 | G29: ='Financial-Summary'!F10*G12 -> 15417391 | H29: ='Financial-Summary'!F11*H12 -> 20792000
B30: Rent | C30: ='Financial-Summary'!G6 -> 2040000 | D30: ='Financial-Summary'!G7 -> 2220000 | E30: ='Financial-Summary'!G8 -> 2178000 | F30: ='Financial-Summary'!G9 -> 2208000 | G30: ='Financial-Summary'!G10 -> 2539200 | H30: ='Financial-Summary'!G11 -> 2539200
B31: One-Time Expenses | C31: ='Financial-Summary'!H6 -> 0 | D31: ='Financial-Summary'!H7 -> 500000 | E31: ='Financial-Summary'!H8 -> 1000000 | F31: ='Financial-Summary'!H9 -> 600000 | G31: ='Financial-Summary'!H10 -> 2000000 | H31: ='Financial-Summary'!H11 -> 3000000
B32: In-House Events | C32: ='Financial-Summary'!I6 -> 500000 | D32: ='Financial-Summary'!I7 -> 575000 | E32: ='Financial-Summary'!I8 -> 661250 | F32: ='Financial-Summary'!I9 -> 760437.5 | G32: ='Financial-Summary'!I10 -> 874503.12 | H32: ='Financial-Summary'!I11 -> 1005678.6
B33: Mktng+Legal+Emergency | C33: ='Financial-Summary'!J6 -> 1000000 | D33: ='Financial-Summary'!J7 -> 1150000 | E33: ='Financial-Summary'!J8 -> 1322500 | F33: ='Financial-Summary'!J9 -> 1520875 | G33: ='Financial-Summary'!J10 -> 1749006.2 | H33: ='Financial-Summary'!J11 -> 2011357.2
B34: Other Expenses | C34: ='Financial-Summary'!K6 -> 400000 | D34: ='Financial-Summary'!K7 -> 480000 | E34: ='Financial-Summary'!K8 -> 576000 | F34: ='Financial-Summary'!K9 -> 691200 | G34: ='Financial-Summary'!K10 -> 829440 | H34: ='Financial-Summary'!K11 -> 995328
B35: Total Expenses | C35: =SUM(C29:C34) -> 6748000 | D35: =SUM(D29:D34) -> 9331400 | E35: =SUM(E29:E34) -> 12686911 | F35: =SUM(F29:F34) -> 16323972 | G35: =SUM(G29:G34) -> 23409541 | H35: =SUM(H29:H34) -> 30343564
B36: Net Income | C36: =C28-C35 -> 752000 | D36: =D28-D35 -> 1649634.5 | E36: =E28-E35 -> 5151945.9 | F36: =F28-F35 -> 7894808.5 | G36: =G28-G35 -> 9440459.3 | H36: =H28-H35 -> 12436436
B37: Net Margin % | C37: =C36/C28 -> 0.10026667 | D37: =D36/D28 -> 0.15022578 | E37: =E36/E28 -> 0.2888047 | F37: =F36/F28 -> 0.32597878 | G37: =G36/G28 -> 0.2873808 | H37: =H36/H28 -> 0.29070678
B39: Net Income Comparison — All Scenarios
C41: 2026-27 | D41: 2027-28 | E41: 2028-29 | F41: 2029-30 | G41: 2030-31 | H41: 2031-32 | I41: 6-Year Total
B42: Conservative | C42: ='Financial-Summary'!M6 -> -1248000 | D42: ='Financial-Summary'!M7 -> -646137.93 | E42: ='Financial-Summary'!M8 -> 1934535.7 | F42: ='Financial-Summary'!M9 -> 2795536.3 | G42: ='Financial-Summary'!M10 -> 2699850.6 | H42: ='Financial-Summary'!M11 -> 3354436.2 | I42: =SUM(C42:H42) -> 8890220.9
B43: Moderate | C43: ='Moderate-Growth'!C36 -> 752000 | D43: ='Moderate-Growth'!D36 -> 1101748.3 | E43: ='Moderate-Growth'!E36 -> 3543240.8 | F43: ='Moderate-Growth'!F36 -> 5461065 | G43: ='Moderate-Growth'!G36 -> 6070155 | H43: ='Moderate-Growth'!H36 -> 7297936.2 | I43: =SUM(C43:H43) -> 24226145
B44: Bullish | C44: =C36 -> 752000 | D44: =D36 -> 1649634.5 | E44: =E36 -> 5151945.9 | F44: =F36 -> 7894808.5 | G44: =G36 -> 9440459.3 | H44: =H36 -> 12436436 | I44: =SUM(C44:H44) -> 37325284
B47: Investor Returns — Scenario Comparison
B48: 15% equity stake | ₹1.75 Cr investment | Investor's share of annual net income
B51: Investor's 15% Income Share by Year
C53: 2026-27 | D53: 2027-28 | E53: 2028-29 | F53: 2029-30 | G53: 2030-31 | H53: 2031-32 | I53: 6-Year Total
B54: Conservative | C54: ='Financial-Summary'!M6*'Investor-Returns'!$D$8 -> -187200 | D54: ='Financial-Summary'!M7*'Investor-Returns'!$D$8 -> -96920.69 | E54: ='Financial-Summary'!M8*'Investor-Returns'!$D$8 -> 290180.36 | F54: ='Financial-Summary'!M9*'Investor-Returns'!$D$8 -> 419330.44 | G54: ='Financial-Summary'!M10*'Investor-Returns'!$D$8 -> 404977.59 | H54: ='Financial-Summary'!M11*'Investor-Returns'!$D$8 -> 503165.43 | I54: =SUM(C54:H54) -> 1333533.1
B55: Moderate | C55: ='Moderate-Growth'!C36*'Investor-Returns'!$D$8 -> 112800 | D55: ='Moderate-Growth'!D36*'Investor-Returns'!$D$8 -> 165262.24 | E55: ='Moderate-Growth'!E36*'Investor-Returns'!$D$8 -> 531486.12 | F55: ='Moderate-Growth'!F36*'Investor-Returns'!$D$8 -> 819159.74 | G55: ='Moderate-Growth'!G36*'Investor-Returns'!$D$8 -> 910523.25 | H55: ='Moderate-Growth'!H36*'Investor-Returns'!$D$8 -> 1094690.4 | I55: =SUM(C55:H55) -> 3633921.8
...

Sheet Fund-Infusion
B2: Fund Infusion — Use of Proceeds
B3: ₹1.75 Crore Investment Allocation & Impact
B6: Existing Loan Obligations
B8: Loan Type | C8: Outstanding (₹) | D8: EMI/Month (₹) | E8: Interest Rate | F8: Tenure
B9: Home Loan | C9: ='Raw-Data'!D49 -> 4000000 | D9: ='Raw-Data'!F49 -> 46000 | E9: — | F9: —
B10: Gold Loan 1 | C10: ='Raw-Data'!D50 -> 2600000 | D10: ='Raw-Data'!F50 -> 22000 | E10: — | F10: —
B11: Gold Loan 2 | C11: ='Raw-Data'!D51 -> 1000000 | D11: ='Raw-Data'!F51 -> 9000 | E11: — | F11: —
B12: Personal Loan | C12: ='Raw-Data'!D52 -> 2000000 | D12: ='Raw-Data'!F52 -> 17000 | E12: ='Raw-Data'!E52 -> 0.1 | F12: ='Raw-Data'!G52 -> 2
B13: Total | C13: =SUM(C9:C12) -> 9600000 | D13: =SUM(D9:D12) -> 94000
B15: Fund Allocation Breakdown
B17: Purpose | C17: Amount (₹) | D17: % of Fund | E17: Details
B18: Board Permissions | C18: ='Raw-Data'!D60 -> 2000000 | D18: =C18/'Investor-Returns'!D9 -> 0.11428571 | E18: Maharashtra Board registration — one-time expense
B19: Loan Repayment | C19: ='Raw-Data'!D61 -> 8000000 | D19: =C19/'Investor-Returns'!D9 -> 0.45714286 | E19: Square off existing loans; reduce EMI burden on working capital
B20: Computer Lab, Library & Soft Play Zone | C20: ='Raw-Data'!D62 -> 2500000 | D20: =C20/'Investor-Returns'!D9 -> 0.14285714 | E20: 30+ computers, state-of-the-art library setup
B21: Sports Turf & Multipurpose Court | C21: ='Raw-Data'!D63 -> 2500000 | D21: =C21/'Investor-Returns'!D9 -> 0.14285714 | E21: Cricket turf, tennis & badminton court — revenue generating asset | F21: ★ Revenue Generating
B22: Working Capital Reserve | C22: ='Raw-Data'!D64 -> 2500000 | D22: =C22/'Investor-Returns'!D9 -> 0.14285714 | E22: Buffer for operational cash flow gaps
B23: Total Fund Utilisation | C23: =SUM(C18:C22) -> 17500000 | D23: =C23/'Investor-Returns'!D9 -> 1
B25: Sports Complex — Additional Revenue Opportunity
B27: ▸ | C27: 10,000+ sq ft ground to be developed as a multi-sport complex
B28: ▸ | C28: Facilities: Cricket/Tennis turf, Badminton & Skating court, Indoor Gymnastics hall
B29: ▸ | C29: School use during school hours; open for public booking after hours
B30: ▸ | C30: Revenue streams: Hourly rentals, coaching academies, weekend tournaments, corporate events
B31: ▸ | C31: Estimated to generate significant recurring revenue independent of school fees

Sheet Financial-Summary
B2: ASTRAL SCHOOL — Nagre Nagar
B3: Financial Projections 2026–2032
B5: Year | C5: Students | D5: Fees Collection | E5: Annual Collection | F5: Staff Expenses | G5: Rent | H5: One-Time Expenses | I5: In-House Events | J5: Mktng+Legal+Emergency | K5: Other Expenses | L5: Total Expenses | M5: Net Income
B6: ='Raw-Data'!A3 -> THIS | C6: ='Raw-Data'!B3 -> 200 | D6: ='Raw-Data'!C3 -> 7500000 | E6: ='Raw-Data'!D3 -> 7500000 | F6: ='Raw-Data'!E3 -> 2808000 | G6: ='Raw-Data'!F3 -> 2040000 | H6: ='Raw-Data'!H3 -> 0 | I6: ='Raw-Data'!I3 -> 500000 | J6: ='Raw-Data'!J3 -> 1000000 | K6: ='Raw-Data'!K3 -> 400000 | L6: ='Raw-Data'!L3 -> 8748000 | M6: ='Raw-Data'!M3 -> -1248000
B7: ='Raw-Data'!A4 -> 2027-28 | C7: ='Raw-Data'!B4 -> 250 | D7: ='Raw-Data'!C4 -> 9150862.1 | E7: ='Raw-Data'!D4 -> 9150862.1 | F7: ='Raw-Data'!E4 -> 3672000 | G7: ='Raw-Data'!F4 -> 2220000 | H7: ='Raw-Data'!H4 -> 500000 | I7: ='Raw-Data'!I4 -> 575000 | J7: ='Raw-Data'!J4 -> 1150000 | K7: ='Raw-Data'!K4 -> 480000 | L7: ='Raw-Data'!L4 -> 9797000 | M7: ='Raw-Data'!M4 -> -646137.93
B8: ='Raw-Data'!A5 -> 2028-29 | C8: ='Raw-Data'!B5 -> 310 | D8: ='Raw-Data'!C5 -> 12568286 | E8: ='Raw-Data'!D5 -> 12568286 | F8: ='Raw-Data'!E5 -> 4896000 | G8: ='Raw-Data'!F5 -> 2178000 | H8: ='Raw-Data'!H5 -> 1000000 | I8: ='Raw-Data'!I5 -> 661250 | J8: ='Raw-Data'!J5 -> 1322500 | K8: ='Raw-Data'!K5 -> 576000 | L8: ='Raw-Data'!L5 -> 10633750 | M8: ='Raw-Data'!M5 -> 1934535.7
B9: ='Raw-Data'!A6 -> 2029-30 | C9: ='Raw-Data'!B6 -> 370 | D9: ='Raw-Data'!C6 -> 15188049 | E9: ='Raw-Data'!D6 -> 15188049 | F9: ='Raw-Data'!E6 -> 6612000 | G9: ='Raw-Data'!F6 -> 2208000 | H9: ='Raw-Data'!H6 -> 600000 | I9: ='Raw-Data'!I6 -> 760437.5 | J9: ='Raw-Data'!J6 -> 1520875 | K9: ='Raw-Data'!K6 -> 691200 | L9: ='Raw-Data'!L6 -> 12392512 | M9: ='Raw-Data'!M6 -> 2795536.3
B10: ='Raw-Data'!A7 -> 2030-31 | C10: ='Raw-Data'!B7 -> 460 | D10: ='Raw-Data'!C7 -> 20148000 | E10: ='Raw-Data'!D7 -> 20148000 | F10: ='Raw-Data'!E7 -> 9456000 | G10: ='Raw-Data'!F7 -> 2539200 | H10: ='Raw-Data'!H7 -> 2000000 | I10: ='Raw-Data'!I7 -> 874503.12 | J10: ='Raw-Data'!J7 -> 1749006.2 | K10: ='Raw-Data'!K7 -> 829440 | L10: ='Raw-Data'!L7 -> 17448149 | M10: ='Raw-Data'!M7 -> 2699850.6
B11: ='Raw-Data'!A8 -> 2031-32 | C11: ='Raw-Data'!B8 -> 540 | D11: ='Raw-Data'!C8 -> 25110000 | E11: ='Raw-Data'!D8 -> 25110000 | F11: ='Raw-Data'!E8 -> 12204000 | G11: ='Raw-Data'!F8 -> 2539200 | H11: ='Raw-Data'!H8 -> 3000000 | I11: ='Raw-Data'!I8 -> 1005678.6 | J11: ='Raw-Data'!J8 -> 2011357.2 | K11: ='Raw-Data'!K8 -> 995328 | L11: ='Raw-Data'!L8 -> 21755564 | M11: ='Raw-Data'!M8 -> 3354436.2

Sheet Staff-Plan
B2: Staff Plan & Growth
B4: Category | C4: Grades | D4: 2026-27 | E4: 2027-28 | F4: 2028-29 | G4: 2029-30 | H4: 2030-31 | I4: 2031-32
B5: Grades Offered | C5: ='Raw-Data'!C11 -> GRADES | D5: ='Raw-Data'!D11 -> PG,NUR,JR,SRKG,1,2 | E5: ='Raw-Data'!E11 -> PG-Gr3 | F5: ='Raw-Data'!F11 -> PG -GRADE 3 | G5: ='Raw-Data'!G11 -> PG -GRADE 4 | H5: ='Raw-Data'!H11 -> PG -GRADE 5 | I5: ='Raw-Data'!I11 -> PG -GRADE 6
B6: Students | C6: ='Raw-Data'!C12 -> no | D6: ='Raw-Data'!D12 -> 200 | E6: ='Raw-Data'!E12 -> 250 | F6: ='Raw-Data'!F12 -> 310 | G6: ='Raw-Data'!G12 -> 370 | H6: ='Raw-Data'!H12 -> 460 | I6: ='Raw-Data'!I12 -> 540
B7: Educators | C7: ='Raw-Data'!C13 -> 0 | D7: ='Raw-Data'!D13 -> 10 | E7: ='Raw-Data'!E13 -> 11 | F7: ='Raw-Data'!F13 -> 14 | G7: ='Raw-Data'!G13 -> 17 | H7: ='Raw-Data'!H13 -> 19 | I7: ='Raw-Data'!I13 -> 21
B8: Aunties | C8: ='Raw-Data'!C14 -> 0 | D8: ='Raw-Data'!D14 -> 3 | E8: ='Raw-Data'!E14 -> 5 | F8: ='Raw-Data'!F14 -> 6 | G8: ='Raw-Data'!G14 -> 7 | H8: ='Raw-Data'!H14 -> 10 | I8: ='Raw-Data'!I14 -> 12
B9: Security Staff | C9: ='Raw-Data'!C15 -> 0 | D9: ='Raw-Data'!D15 -> 2 | E9: ='Raw-Data'!E15 -> 2 | F9: ='Raw-Data'!F15 -> 2 | G9: ='Raw-Data'!G15 -> 2 | H9: ='Raw-Data'!H15 -> 3 | I9: ='Raw-Data'!I15 -> 3
B10: Visiting Faculty | C10: ='Raw-Data'!C16 -> 0 | D10: ='Raw-Data'!D16 -> 4 | E10: ='Raw-Data'!E16 -> 4 | F10: ='Raw-Data'!F16 -> 5 | G10: ='Raw-Data'!G16 -> 5 | H10: ='Raw-Data'!H16 -> 5 | I10: ='Raw-Data'!I16 -> 7
B11: Administrative Staff | C11: ='Raw-Data'!C17 -> 0 | D11: ='Raw-Data'!D17 -> 1 | E11: ='Raw-Data'!E17 -> 1 | F11: ='Raw-Data'!F17 -> 1 | G11: ='Raw-Data'!G17 -> 1 | H11: ='Raw-Data'!H17 -> 2 | I11: ='Raw-Data'!I17 -> 2
B12: Principal & HM | C12: ='Raw-Data'!C18 -> 0 | D12: ='Raw-Data'!D18 -> 0 | E12: ='Raw-Data'!E18 -> 0 | F12: ='Raw-Data'!F18 -> 0 | G12: ='Raw-Data'!G18 -> 0 | H12: ='Raw-Data'!H18 -> 1 | I12: ='Raw-Data'!I18 -> 1
B13: Total Staff | D13: =SUM(D7:D12) -> 20 | E13: =SUM(E7:E12) -> 23 | F13: =SUM(F7:F12) -> 28 | G13: =SUM(G7:G12) -> 32 | H13: =SUM(H7:H12) -> 40 | I13: =SUM(I7:I12) -> 46

Sheet Student-Growth
B2: Student Growth — Historical & Projected
B3: COVID impact noted in 2020-21
C5: 2018-19 | D5: 2019-20 | E5: 2020-21 | F5: 2021-22 | G5: 2022-23 | H5: 2023-24 | I5: 2024-25 | J5: 2025-26 | K5: 2026-27
B6: Nagre Nagar | C6: ='Raw-Data'!B27 -> 60 | D6: ='Raw-Data'!C27 -> 104 | E6: ='Raw-Data'!D27 -> 45 | F6: ='Raw-Data'!E27 -> 55 | G6: ='Raw-Data'!F27 -> 90 | H6: ='Raw-Data'!G27 -> 120 | I6: ='Raw-Data'!H27 -> 145 | J6: ='Raw-Data'!I27 -> 155 | K6: ='Raw-Data'!J27 -> 200
B7: Govind Nagar | C7: ='Raw-Data'!B28 -> 0 | D7: ='Raw-Data'!C28 -> 0 | E7: ='Raw-Data'!D28 -> 0 | F7: ='Raw-Data'!E28 -> 0 | G7: ='Raw-Data'!F28 -> 0 | H7: ='Raw-Data'!G28 -> 0 | I7: ='Raw-Data'!H28 -> 65 | J7: ='Raw-Data'!I28 -> 95 | K7: ='Raw-Data'!J28 -> 130
B8: Total | C8: ='Raw-Data'!B29 -> 60 | D8: ='Raw-Data'!C29 -> 104 | E8: ='Raw-Data'!D29 -> 45 | F8: ='Raw-Data'!E29 -> 55 | G8: ='Raw-Data'!F29 -> 90 | H8: ='Raw-Data'!G29 -> 120 | I8: ='Raw-Data'!H29 -> 210 | J8: ='Raw-Data'!I29 -> 250 | K8: ='Raw-Data'!J29 -> 330

Sheet Notes
B2: Investor Notes
B5: 1 | C5: The numbers will be achieved since we have two preschools — one in Nagre Nagar and second in Govind Nagar.
B6: 2 | C6: We intend to launch 1 more preschool in Ranvishankar Marg or Pathardi in the next two years, which will increase numbers at pre-primary level, thus ensuring subsequent growth in Grade 1 and 2 numbers.
B7: 3 | C7: The investor will have a share in Nagre Nagar school which now goes under the banner Excelerate Learning Foundation.
B8: 4 | C8: Govind Nagar and any other preschool started in near future will continue to remain standalone entities.
B9: 5 | C9: Constructed area is 8,500 sq ft (classrooms only). We intend to construct a hall of 2,500 sq ft separately for dance and other indoor activities.

Sheet Raw-Data
A2: YEAR | B2: NUMBER | C2: FEES | D2: ANNUAL COLLECTION | E2: STAFF EXPENSES | F2: rent | G2: ONE TIME EXPENSE | H2: PROVISION | I2: IN HOUSE EVENTS | J2: MKTNG+LEGAL+EMERGENCY | K2: OTHER EXPENSES(App+bills+Staff welness+Maintainance up keep+travel) | L2: TOTAL EXPENSES | M2: INCOME
A3: THIS | B3: 200 | C3: 7500000 | D3: =C3 -> 7500000 | E3: =D19 -> 2808000 | F3: =((170000*12)) -> 2040000 | G3: 2000000 | I3: 500000 | J3: 1000000 | K3: 400000 | L3: =E3+F3+H3+I3+J3+K3+G3 -> 8748000 | M3: =D3-L3 -> -1248000
A4: 2027-28 | B4: 250 | C4: =B4*E22 -> 9150862.1 | D4: =C4 -> 9150862.1 | E4: =E21 -> 3672000 | F4: =((185000*12)) -> 2220000 | G4: 1200000 | H4: 500000 | I4: =(I3*15%)+I3 -> 575000 | J4: =(J3*15%)+J3 -> 1150000 | K4: =(K3*20%)+K3 -> 480000 | L4: =E4+F4+H4+I4+J4+K4+G4 -> 9797000 | M4: =D4-L4 -> -646137.93
A5: 2028-29 | B5: 310 | C5: =B5*F22 -> 12568286 | D5: =C5 -> 12568286 | E5: =F21 -> 4896000 | F5: =(165000+(165000*10%))*12 -> 2178000 | H5: 1000000 | I5: =(I4*15%)+I4 -> 661250 | J5: =(J4*15%)+J4 -> 1322500 | K5: =(K4*20%)+K4 -> 576000 | L5: =E5+F5+H5+I5+J5+K5+G5 -> 10633750 | M5: =D5-L5 -> 1934535.7
A6: 2029-30 | B6: 370 | C6: =B6*G22 -> 15188049 | D6: =C6 -> 15188049 | E6: =G21 -> 6612000 | F6: =(160000+(160000*15%))*12 -> 2208000 | H6: 600000 | I6: =(I5*15%)+I5 -> 760437.5 | J6: =(J5*15%)+J5 -> 1520875 | K6: =(K5*20%)+K5 -> 691200 | L6: =E6+F6+H6+I6+J6+K6+G6 -> 12392512 | M6: =D6-L6 -> 2795536.3
A7: 2030-31 | B7: 460 | C7: =B7*H22 -> 20148000 | D7: =C7 -> 20148000 | E7: =H21 -> 9456000 | F7: =211600*12 -> 2539200 | H7: 2000000 | I7: =(I6*15%)+I6 -> 874503.12 | J7: =(J6*15%)+J6 -> 1749006.2 | K7: =(K6*20%)+K6 -> 829440 | L7: =E7+F7+H7+I7+J7+K7+G7 -> 17448149 | M7: =D7-L7 -> 2699850.6
A8: 2031-32 | B8: 540 | C8: =B8*I22 -> 25110000 | D8: =C8 -> 25110000 | E8: =I21 -> 12204000 | F8: =211600*12 -> 2539200 | H8: 3000000 | I8: =(I7*15%)+I7 -> 1005678.6 | J8: =(J7*15%)+J7 -> 2011357.2 | K8: =(K7*20%)+K7 -> 995328 | L8: =E8+F8+H8+I8+J8+K8+G8 -> 21755564 | M8: =D8-L8 -> 3354436.2
B10: year | D10: 2026-27 | E10: 2027-28 | F10: 2028-29 | G10: 2029-30 | H10: 2030-31 | I10: 2031-32
B11: expenses break up | C11: GRADES | D11: PG,NUR,JR,SRKG,1,2 | E11: PG-Gr3 | F11: PG -GRADE 3 | G11: PG -GRADE 4 | H11: PG -GRADE 5 | I11: PG -GRADE 6
B12: expenses | C12: no | D12: =B3 -> 200 | E12: =B4 -> 250 | F12: =B5 -> 310 | G12: =B6 -> 370 | H12: =B7 -> 460 | I12: =B8 -> 540
B13: educators | D13: 10 | E13: 11 | F13: 14 | G13: 17 | H13: 19 | I13: 21
B14: aunties | D14: 3 | E14: 5 | F14: 6 | G14: 7 | H14: 10 | I14: 12
B15: security staff | D15: 2 | E15: 2 | F15: 2 | G15: 2 | H15: 3 | I15: 3
B16: visiting faculty | D16: 4 | E16: 4 | F16: 5 | G16: 5 | H16: 5 | I16: 7
B17: Administrative staff | D17: 1 | E17: 1 | F17: 1 | G17: 1 | H17: 2 | I17: 2
B18: PRINCIPAL& HM | D18: 0 | E18: 0 | F18: 0 | G18: 0 | H18: 1 | I18: 1
D19: =((D13*12000)+(D14*8000)+(D15*20000)+(D16*10000)+(D17*10000)+D18)*12 -> 2808000 | E19: =((E13*14000)+(E14*9000)+(E15*22000)+(E16*12000)+(E17*15000)+E18)*12 -> 3672000 | F19: =((F13*15000)+(F14*10000)+(F15*23000)+(F16*15000)+(F17*17000)+F18)*12 -> 4896000 | G19: =((G13*18000)+(G14*11000)+(G15*24000)+(G16*20000)+(G17*20000)+(G18*35000))*12 -> 6612000 | H19: =((H13*21000)+(H14*12000)+(H15*25000)+(H16*21000)+(H17*22000)+(H18*45000))*12 -> 9456000 | I19: =((I13*25000)+(I14*13000)+(I15*26000)+(I16*22000)+(I17*28000)+(I18*48000))*12 -> 12204000
E20: 0 | F20: 0 | G20: 0 | H20: 0 | I20: 0
E21: =E19+E20 -> 3672000 | F21: =F19+F20 -> 4896000 | G21: =G19+G20 -> 6612000 | H21: =H19+H20 -> 9456000 | I21: =I19+I20 -> 12204000
B22: Revenue per Student (₹) | C22: Nagre Nagar driver | D22: =C3/B3 -> 37500 | E22: =10615000/290 -> 36603.448 | F22: =14190000/350 -> 40542.857 | G22: =16830000/410 -> 41048.78 | H22: =21900000/500 -> 43800 | I22: =26970000/580 -> 46500
D25: COVID HIT SCHOOL WENT ONLINE
B26: 2018-19 | C26: 2019-20 | D26: 2020-21 | E26: 2021-22 | F26: 2022-23 | G26: 2023-24 | H26: 2024-25 | I26: 2025-26 | J26: 2026-2027
A27: Student Strength Nagre Nagar | B27: 60 | C27: 104 | D27: 45 | E27: 55 | F27: 90 | G27: 120 | H27: 145 | I27: =130+25 -> 155 | J27: =B3 -> 200
A28: Student Strength Govind Nagar | H28: 65 | I28: 95 | J28: 130
A29: TOTAL | B29: 60 | C29: 104 | D29: 45 | E29: 55 | F29: 90 | G29: 120 | H29: =H27+H28 -> 210 | I29: =I27+I28 -> 250 | J29: =J27+J28 -> 330
B32: NOTES
B33: The numbers will be achieved since we have two preschools one in Nagre nagar and second in Govind nagar
B35: We intend to launch 1 more preschool in Ranvishankar marg or pathardi in the next two years WHICH WILL RAKE UP NUMBERS AT PRE PRIMARY LEVEL THUS ENSURING SUBSEQUENT GROWTH IN GRADE 1 AND 2 NUMBERS
B37: The investor will have a share in Nagre nagar school which now goes under the banner Excelerate Learning Foundation
B39: Govind Nagar and any other preschool started in near future will continue to remain standalone entites
B45: CONTRUCTED AREA | C45: constructed area is 8500 sqft. These are classes only we intend to construct a hall of 2500 sqft separately for dance and other indoor activities
C47: LOANS TAKEN TOWARDS CONSTRUCTION
C48: Type | E48: INTREST RATE | F48: EMI | G48: TENURE YRS
C49: Home loan | D49: 4000000 | E49: 0.1025 | F49: 46000 | G49: 15
C50: Gold loan 1 | D50: 2600000 | E50: 0.098 | F50: 22000 | G50: FLEXI
C51: Gold Loan 2 | D51: 1000000 | E51: 0.098 | F51: 9000 | G51: FLEXI
C52: Personal loan | D52: 2000000 | E52: 0.1 | F52: 17000 | G52: 2
C57: FUND INFUSION USE
C59: AMOUNT WILL BE USED TO
C60: PERMISSION FROM EDUCATIONAL BOARD | D60: 2000000 | E60: ONE TIME EXPENSE TOWARDS MAHARASTRA BOARD PERMISSIONS
...

Sheet Share-Valuation
B2: EXCELERATE LEARNING FOUNDATION
B3: QTR. A1 AMBAD LINK RD, CIDCO NASHIK, Trimurti Chowk, Nashik, Nashik,Maharashtra, India, 422008
B4: CIN : U88900MH2025NPL445351
B6: Particulars | C6: As at 31st March 2026
B8: ASSETS
B9: Non-current assets
B10: Property,Plant and Equipment and Intangible assets
B11: Property,Plant and Equipment | C11: 14976444
B12: Intangible assets | C12: 0
B13: Capital work-in-Progress | C13: 0
B14: Intangible assets under development | C14: 0
B16: Non-current investments | C16: 0
B17: Deferred tax assets (net) | C17: 0
B18: Long-term loans and advances | C18: 0
B19: Other non-current assets | C19: 0
C20: =SUM(C11:C14)+SUM(C16:C19) -> 14976444
B21: Current assets
B22: Current investments | C22: 0
B23: Inventories | C23: 0
B24: Trade receivables | C24: 0
B25: Cash and cash equivalents | C25: 2346984
B26: Short-term loans and advances | C26: 0
B27: Other current assets | C27: 810560
C28: =SUM(C22:C27) -> 3157544
B29: TOTAL ASSETS | C29: =C20+C28 -> 18133988
B31: LIABILITIES
B32: Non-current liabilities
B33: Long-term borrowings | C33: 0
B34: Deferred tax liabilities (Net) | C34: 775
B35: Other long term liabilities | C35: 0
B36: Long-term provisions | C36: 0
C37: 0
B38: Current liabilities
B39: Short-term borrowings | C39: 16228191
B40: Trade payables
B41: (A) Micro enterprises and small enterprises | C41: 0
B42: (B) Others | C42: 0
B43: Other current liabilities | C43: 0
B44: Short-term provisions | C44: 0
C45: 16228966
...

Sheet Investor-Pitch
B2: ASTRAL SCHOOL — INVESTOR PITCH
B3: Excelerate Learning Foundation | Equity raise & growth plan
B5: Investment Snapshot
B7: Metric | C7: Value | D7: Unit | E7: Investor Relevance
B8: Price per 1% Equity | C8: 1000000 | D8: ₹ / 1% | E8: User-approved pitch input
B9: Base Equity Offered | C9: 0.1 | D9: % | E9: Base case
B10: Base Raise | C10: =C8*(C9/1%) -> 10000000 | D10: ₹ | E10: 10% equity at ₹10 lakh per 1%
B11: Implied Post-Money Valuation | C11: =C8/1% -> 100000000 | D11: ₹ | E11: Negotiated pitch valuation
B12: Implied Pre-Money Valuation | C12: =C11-C10 -> 90000000 | D12: ₹ | E12: Post-money less base raise
B13: CA Reference Per Share | C13: ='Share-Valuation'!C50 -> 31 | D13: ₹ / share | E13: Rounded CA reference; separate from pitch price
B14: Current Students | C14: ='Financial-Summary'!C6 -> 200 | D14: students | E14: User-provided pitch assumption
B15: Current Revenue | C15: ='Financial-Summary'!E6 -> 7500000 | D15: ₹ / year | E15: Approximate at 200 students
B16: Key Loans | C16: ='Fund-Infusion'!C13 -> 9600000 | D16: ₹ | E16: Linked detailed obligations
B17: Current EMI | C17: ='Fund-Infusion'!D13 -> 94000 | D17: ₹ / month | E17: Linked current monthly EMI
B20: Equity Price Card
B22: Equity Stake | C22: Investment (₹) | D22: Implied Post-Money (₹) | E22: Notes
B23: 0.01 | C23: =$C$8*(B23/1%) -> 1000000 | D23: =C23/B23 -> 100000000 | E23: Entry ticket
B24: 0.05 | C24: =$C$8*(B24/1%) -> 5000000 | D24: =C24/B24 -> 100000000 | E24: Smaller strategic participation
B25: 0.1 | C25: =$C$8*(B25/1%) -> 10000000 | D25: =C25/B25 -> 100000000 | E25: Base pitch
B26: 0.15 | C26: =$C$8*(B26/1%) -> 15000000 | D26: =C26/B26 -> 100000000 | E26: Larger strategic participation
B29: Use of Funds — Base Raise
B31: Use | C31: Allocation | D31: Amount (₹) | E31: Purpose | F31: Investor Impact | G31: Balance Check
B32: Loan repayment / EMI reduction | C32: 0.45 | D32: =$C$10*C32 -> 4500000 | E32: Square off selected loans gradually | F32: Lower monthly burden and improve cash retention
B33: Learning facilities | C33: 0.25 | D33: =$C$10*C33 -> 2500000 | E33: Computer lab, library, soft-play and classroom upgrades | F33: Improve school proposition and capacity
B34: Sports / activity facilities | C34: 0.15 | D34: =$C$10*C34 -> 1500000 | E34: Sports turf, multipurpose court and activity zone | F34: Additional revenue potential
B35: Working capital / execution reserve | C35: 0.15 | D35: =$C$10*C35 -> 1500000 | E35: Operational buffer during build-out | F35: Protect delivery and cash flow
B36: Total Planned Use | C36: =SUM(C32:C35) -> 1 | D36: =SUM(D32:D35) -> 10000000 | E36: 100% of base raise | F36: Must equal base raise | G36: =IF(D36=$C$10,"OK","CHECK") -> OK
B38: Illustrative EMI Relief (not a lender quote) | D38: =D32/$C$16*$C$17 -> 44062.5 | E38: If repayments reduce obligations pro rata | F38: Estimated monthly relief
B39: Illustrative Annual EMI Relief | D39: =D38*12 -> 528750 | E39: Monthly relief × 12 | F39: Reinvest in operations or growth
B42: Growth Outlook — Moderate Scenario
B44: Year | C44: Students | D44: Revenue (₹) | E44: Net Income (₹) | F44: Net Margin
B45: ='Moderate-Growth'!C8 -> 2026-27 | C45: ='Moderate-Growth'!C10 -> 200 | D45: ='Moderate-Growth'!C28 -> 7500000 | E45: ='Moderate-Growth'!C36 -> 752000 | F45: ='Moderate-Growth'!C37 -> 0.10026667
B46: ='Moderate-Growth'!D8 -> 2027-28 | C46: ='Moderate-Growth'!D10 -> 275 | D46: ='Moderate-Growth'!D28 -> 10065948 | E46: ='Moderate-Growth'!D36 -> 1101748.3 | F46: ='Moderate-Growth'!D37 -> 0.109453
B47: ='Moderate-Growth'!E8 -> 2028-29 | C47: ='Moderate-Growth'!E10 -> 375 | D47: ='Moderate-Growth'!E28 -> 15203571 | E47: ='Moderate-Growth'!E36 -> 3543240.8 | F47: ='Moderate-Growth'!E37 -> 0.23305319
B48: ='Moderate-Growth'!F8 -> 2029-30 | C48: ='Moderate-Growth'!F10 -> 485 | D48: ='Moderate-Growth'!F28 -> 19908659 | E48: ='Moderate-Growth'!F36 -> 5461065 | F48: ='Moderate-Growth'!F37 -> 0.27430602
B49: ='Moderate-Growth'!G8 -> 2030-31 | C49: ='Moderate-Growth'!G10 -> 605 | D49: ='Moderate-Growth'!G28 -> 26499000 | E49: ='Moderate-Growth'!G36 -> 6070155 | F49: ='Moderate-Growth'!G37 -> 0.2290711
B50: ='Moderate-Growth'!H8 -> 2031-32 | C50: ='Moderate-Growth'!H10 -> 705 | D50: ='Moderate-Growth'!H28 -> 32782500 | E50: ='Moderate-Growth'!H36 -> 7297936.2 | F50: ='Moderate-Growth'!H37 -> 0.22261683
B51: 6-Year Revenue CAGR | D51: =(D50/D45)^(1/5)-1 -> 0.34312416
B52: 6-Year Cumulative Net Income | E52: =SUM(E45:E50) -> 24226145
B55: Growth Outlook — Bullish Scenario
...

Sheet Investor-Pitch-2
B2: ASTRAL SCHOOL — INVESTOR PITCH 2
B3: Excelerate Learning Foundation | Equity raise at ₹15 lakh per 1% equity
B5: Investment Snapshot
B7: Metric | C7: Value | D7: Unit | E7: Investor Relevance
B8: Price per 1% Equity | C8: 1500000 | D8: ₹ / 1% | E8: Alternative pitch input
B9: Base Equity Offered | C9: 0.1 | D9: % | E9: Base case
B10: Base Raise | C10: =C8*(C9/1%) -> 15000000 | D10: ₹ | E10: 10% equity at ₹15 lakh per 1%
B11: Implied Post-Money Valuation | C11: =C8/1% -> 150000000 | D11: ₹ | E11: Negotiated pitch valuation
B12: Implied Pre-Money Valuation | C12: =C11-C10 -> 135000000 | D12: ₹ | E12: Post-money less base raise
B13: CA Reference Per Share | C13: ='Share-Valuation'!C50 -> 31 | D13: ₹ / share | E13: Rounded CA reference; separate from pitch price
B14: Current Students | C14: ='Financial-Summary'!C6 -> 200 | D14: students | E14: User-provided pitch assumption
B15: Current Revenue | C15: ='Financial-Summary'!E6 -> 7500000 | D15: ₹ / year | E15: Approximate at 200 students
B16: Key Loans | C16: ='Fund-Infusion'!C13 -> 9600000 | D16: ₹ | E16: Linked detailed obligations
B17: Current EMI | C17: ='Fund-Infusion'!D13 -> 94000 | D17: ₹ / month | E17: Linked current monthly EMI
B20: Equity Price Card — ₹15 Lakh per 1%
B22: Equity Stake | C22: Investment (₹) | D22: Implied Post-Money (₹) | E22: Notes
B23: 0.01 | C23: =$C$8*(B23/1%) -> 1500000 | D23: =C23/B23 -> 150000000 | E23: Entry ticket
B24: 0.05 | C24: =$C$8*(B24/1%) -> 7500000 | D24: =C24/B24 -> 150000000 | E24: Smaller strategic participation
B25: 0.1 | C25: =$C$8*(B25/1%) -> 15000000 | D25: =C25/B25 -> 150000000 | E25: Base pitch
B26: 0.15 | C26: =$C$8*(B26/1%) -> 22500000 | D26: =C26/B26 -> 150000000 | E26: Larger strategic participation
B29: Use of Funds — ₹1.50 Crore Base Raise
B31: Use | C31: Allocation | D31: Amount (₹) | E31: Purpose | F31: Investor Impact | G31: Balance Check
B32: Loan repayment / EMI reduction | C32: 0.45 | D32: =$C$10*C32 -> 6750000 | E32: Square off selected loans gradually | F32: Lower monthly burden and improve cash retention
B33: Learning facilities | C33: 0.25 | D33: =$C$10*C33 -> 3750000 | E33: Computer lab, library, soft-play and classroom upgrades | F33: Improve school proposition and capacity
B34: Sports / activity facilities | C34: 0.15 | D34: =$C$10*C34 -> 2250000 | E34: Sports turf, multipurpose court and activity zone | F34: Additional revenue potential
B35: Working capital / execution reserve | C35: 0.15 | D35: =$C$10*C35 -> 2250000 | E35: Operational buffer during build-out | F35: Protect delivery and cash flow
B36: Total Planned Use | C36: =SUM(C32:C35) -> 1 | D36: =SUM(D32:D35) -> 15000000 | E36: 100% of base raise | F36: Must equal base raise | G36: =IF(D36=$C$10,"OK","CHECK") -> OK
B38: Illustrative EMI Relief (not a lender quote) | D38: =D32/$C$16*$C$17 -> 66093.75 | E38: If repayments reduce obligations pro rata | F38: Estimated monthly relief
B39: Illustrative Annual EMI Relief | D39: =D38*12 -> 793125 | E39: Monthly relief × 12 | F39: Reinvest in operations or growth
B42: Growth Outlook — Moderate Scenario
B44: Year | C44: Students | D44: Revenue (₹) | E44: Net Income (₹) | F44: Net Margin
B45: ='Moderate-Growth'!C8 -> 2026-27 | C45: ='Moderate-Growth'!C10 -> 200 | D45: ='Moderate-Growth'!C28 -> 7500000 | E45: ='Moderate-Growth'!C36 -> 752000 | F45: ='Moderate-Growth'!C37 -> 0.10026667
B46: ='Moderate-Growth'!D8 -> 2027-28 | C46: ='Moderate-Growth'!D10 -> 275 | D46: ='Moderate-Growth'!D28 -> 10065948 | E46: ='Moderate-Growth'!D36 -> 1101748.3 | F46: ='Moderate-Growth'!D37 -> 0.109453
B47: ='Moderate-Growth'!E8 -> 2028-29 | C47: ='Moderate-Growth'!E10 -> 375 | D47: ='Moderate-Growth'!E28 -> 15203571 | E47: ='Moderate-Growth'!E36 -> 3543240.8 | F47: ='Moderate-Growth'!E37 -> 0.23305319
B48: ='Moderate-Growth'!F8 -> 2029-30 | C48: ='Moderate-Growth'!F10 -> 485 | D48: ='Moderate-Growth'!F28 -> 19908659 | E48: ='Moderate-Growth'!F36 -> 5461065 | F48: ='Moderate-Growth'!F37 -> 0.27430602
B49: ='Moderate-Growth'!G8 -> 2030-31 | C49: ='Moderate-Growth'!G10 -> 605 | D49: ='Moderate-Growth'!G28 -> 26499000 | E49: ='Moderate-Growth'!G36 -> 6070155 | F49: ='Moderate-Growth'!G37 -> 0.2290711
B50: ='Moderate-Growth'!H8 -> 2031-32 | C50: ='Moderate-Growth'!H10 -> 705 | D50: ='Moderate-Growth'!H28 -> 32782500 | E50: ='Moderate-Growth'!H36 -> 7297936.2 | F50: ='Moderate-Growth'!H37 -> 0.22261683
B51: 6-Year Revenue CAGR | D51: =(D50/D45)^(1/5)-1 -> 0.34312416
B52: 6-Year Cumulative Net Income | E52: =SUM(E45:E50) -> 24226145
B55: Growth Outlook — Bullish Scenario
...
