Workbook

Sheet Summary
B2: ASTRAL SCHOOL — VALUATION SUMMARY
B3: Excelerate Learning Foundation, Nagre Nagar, Nashik · CIN U88900MH2025NPL445351
B4: Valuation date 31 March 2026 · basis: audited FY 2025-26 · PRELIMINARY, subject to the open questions
B6: THE BUSINESS TODAY
B7: Metric | C7: Value
B8: Revenue, FY26 audited | C8: ='Audited Base'!$C$7 -> 6090900 | F8: 155 students at Nagre Nagar
B9: Adjusted EBITDA, FY26 | C9: ='Audited Base'!$C$25 -> 2274220 | F9: After normalising loan and non-cash items
B10: Profit after tax, FY26 | C10: 1258940 | F10: The company is profitable
B11: Book equity | C11: ='Audited Base'!$C$32 -> 1318945 | F11: 6,000 shares — ₹220 per share, not ₹31
B12: Net debt | C12: ='Audited Base'!$C$37 -> 13881206 | F12: Unsecured borrowings less cash
B13: Net debt ÷ EBITDA | C13: ='Audited Base'!$C$37/'Audited Base'!$C$25 -> 6.1037217 | F13: Highly leveraged for this size
B15: VALUATION RANGE — EQUITY VALUE (₹ lakh)
B16: Method | C16: Low | D16: High | E16: Mid | F16: Basis
B17: Net asset value | C17: 13.18945 | D17: 13.18945 | E17: =AVERAGE(C17:D17) -> 13.18945 | F17: Floor. Land is leased.
B18: Revenue multiple, 3.0x – 5.0x | C18: 43.91494 | D18: 165.73294 | E18: =AVERAGE(C18:D18) -> 104.82394 | F18: Applied to audited FY26 revenue
B19: EBITDA multiple, 10.0x – 15.0x | C19: 88.60994 | D19: 202.32094 | E19: =AVERAGE(C19:D19) -> 145.46544 | F19: Applied to adjusted FY26 EBITDA
B20: DCF — Case A, organic | C20: -4.8051918 | D20: 79.797077 | E20: =AVERAGE(C20:D20) -> 37.495943 | F20: Pre-money: excludes the raise
B21: DCF — Case B, mgmt conservative | C21: 63.230372 | D21: 200.09664 | E21: =AVERAGE(C21:D21) -> 131.66351 | F21: Assumes the raise is received
B22: DCF — Case C, mgmt moderate | C22: 127.04487 | D22: 312.38237 | E22: =AVERAGE(C22:D22) -> 219.71362 | F22: Assumes the raise plus a third preschool
B23: CONCLUDED RANGE — PRE-MONEY EQUITY | C23: 45 | D23: 200 | E23: =AVERAGE(C23:D23) -> 122.5 | F23: ≈ ₹0.45 Cr to ₹2.00 Cr, midpoint ₹1.22 Cr
B24: Client expectation (₹10 lakh per 1%) | C24: 1000 | D24: 1000 | E24: 1000 | F24: =E24/E23 -> 8.1632653
B26: WHAT THIS MEANS FOR THE RAISE
B27: Pre-money valuation | C27: ₹2 Cr buys | D27: Promoter retains | E27: Verdict
B28: 12200000 | C28: 0.62111801 | D28: 0.37888199 | E28: Promoter loses control
B29: 20000000 | C29: 0.5 | D29: 0.5 | E29: Marginal
B30: 40000000 | C30: 0.33333333 | D30: 0.66666667 | E30: Workable
B31: 100000000 | C31: 0.16666667 | D31: 0.83333333 | E31: Workable
B33: At the midpoint of our range, ₹2 crore of equity would buy 62% of the school and the owner would lose control. This is the central finding: ₹2 crore cannot be raised as equity at any valuation we can defend. It points to debt, or to a smaller raise, or to equity in a separate for-profit vehicle for the commercial activities.
B35: HOW THIS DIFFERS FROM THE MANAGEMENT REPORT
B36: • Tax is included. The management projections contain no tax line at any point.
B37: • The arithmetic error in the Financial-Summary expense total (₹67.48 L of lines against a stated ₹87.48 L) is corrected, and the ₹20 L one-time item is applied consistently across all three scenarios.
B38: • Net debt of ₹1.39 crore is deducted to get from enterprise value to equity value. The management report does not do this.
B39: • Case A values the business without the ₹2 crore, which is the correct pre-money basis. The management report values the company on post-money projections and then sells equity at that price.
B40: • Book equity is ₹13.19 lakh and ₹220 per share, not ₹19.05 lakh and ₹31 per share.

Sheet Audited Base
B2: AUDITED BASE AND NORMALISATION
B3: Excelerate Learning Foundation · FY 2025-26 · audited by Ulhas Borse & Co, UDIN 26161661CUAYAX4200
B5: STATEMENT OF PROFIT AND LOSS AS REPORTED
B6: Particulars | C6: ₹ | D6: ₹ lakh | E6: Source
B7: Revenue from operations | C7: 6090900 | D7: =C7/100000 -> 60.909 | E7: P&L, Note 10
B8: Other income | C8: 19540 | D8: =C8/100000 -> 0.1954 | E8: P&L, Note 11
B9: Employee benefit expenses | C9: -1007680 | D9: =C9/100000 -> -10.0768 | E9: P&L, Note 12
B10: Finance costs | C10: -91700 | D10: =C10/100000 -> -0.917 | E10: P&L, Note 13
B11: Depreciation and amortisation | C11: -22650 | D11: =C11/100000 -> -0.2265 | E11: P&L, Note 14
B12: Other expenses | C12: -3214710 | D12: =C12/100000 -> -32.1471 | E12: P&L, Note 15
B13: Profit before tax | C13: =SUM(C7:C12) -> 1773700 | D13: =C13/100000 -> 17.737 | E13: Agrees to P&L
B14: Current and deferred tax | C14: -514760 | D14: =C14/100000 -> -5.1476 | E14: P&L, Notes 16-17
B15: Profit after tax | C15: =C13+C14 -> 1258940 | D15: =C15/100000 -> 12.5894 | E15: Effective rate 29.0%
B17: NORMALISED EBITDA
B18: Build-up | C18: ₹ | D18: ₹ lakh | E18: Basis for the adjustment
B19: Profit before tax | C19: 1773700 | D19: =C19/100000 -> 17.737 | E19: As reported
B20: Add back finance costs | C20: 91700 | D20: =C20/100000 -> 0.917 | E20: Below the EBITDA line
B21: Add back depreciation and amortisation | C21: 22650 | D21: =C21/100000 -> 0.2265 | E21: Non-cash
B22: Add back loan insurance, processing and legal fees | C22: 203070 | D22: =C22/100000 -> 2.0307 | E22: Financing costs sitting in other expenses — Note 15
B23: Add back stamp duty on lease, 1/5 amortisation | C23: 202640 | D23: =C23/100000 -> 2.0264 | E23: Non-cash amortisation of a capitalised cost — Note 15
B24: Less other income (bank interest) | C24: -19540 | D24: =C24/100000 -> -0.1954 | E24: Not operating
B25: Adjusted EBITDA | C25: =SUM(C19:C24) -> 2274220 | D25: =C25/100000 -> 22.7422 | E25: Margin on revenue
B26: Adjusted EBITDA margin | C26: =C25/C7 -> 0.37337996 | E26: Unusually high — see Open Questions, item 3
B28: BALANCE SHEET AND NET DEBT
B29: Particulars | C29: ₹ | D29: ₹ lakh | E29: Source
B30: Total assets | C30: 18133990 | D30: =C30/100000 -> 181.3399 | E30: Balance sheet
B31: Total liabilities (incl. ₹5,86,080 short-term provisions) | C31: -16815045 | D31: =C31/100000 -> -168.15045 | E31: Balance sheet, Notes 4-6 and Note 5
B32: Net assets / book equity | C32: =SUM(C30:C31) -> 1318945 | D32: =C32/100000 -> 13.18945 | E32: Agrees to shareholder funds ₹13,18,940
B33: Shares outstanding | C33: 6000 | E33: Note 1: 6,000 shares of ₹10. NOT 60,000.
B34: Book value per share | C34: =C32/C33 -> 219.82417 | E34: Management report states ₹31 — overstated share count and omitted provisions
B35: Short-term borrowings (unsecured) | C35: 16228190 | D35: =C35/100000 -> 162.2819 | E35: Note 6
B36: Less cash and cash equivalents | C36: -2346984 | D36: =C36/100000 -> -23.46984 | E36: Note 9
B37: NET DEBT | C37: =C35+C36 -> 13881206 | D37: =C37/100000 -> 138.81206 | E37: Deducted from enterprise value throughout
B39: All figures converted from the thousands used in the audited statements. FY 2024-25 comparatives are nil throughout: the company was incorporated during FY 2025-26, so this is its first reporting period.

Sheet Assumptions
B2: ASSUMPTIONS
B3: Blue cells are inputs. Every projection and valuation on later tabs is driven from here.
B5: VALUATION PARAMETERS
B6: Fee per student, FY26 actual (₹) | C6: 39296.129 | I6: Audited revenue ₹60,90,900 ÷ 155 students
B7: Fee inflation per annum | C7: 0.07 | I7: Management assumes 3.6%; 7% reflects Indian private school fee inflation
B8: Effective tax rate | C8: 0.26 | I8: 25% plus cess. Management projections contain NO tax line at all.
B9: WACC (discount rate) | C9: 0.19 | I9: See build-up on the DCF tab
B10: Terminal growth rate | C10: 0.05 | I10: Nominal long-run growth
B11: Maintenance capex, % of revenue | C11: 0.04 | I11: Excludes the growth capex funded by the raise
B12: Rent, FY27 base (₹) | C12: 1200000 | I12: Audited FY26 rent was ₹8,04,340; management projects ₹20,40,000 — unexplained
B13: Rent growth per annum | C13: 0.05 | I13: Assumed escalation
B15: FEE PER STUDENT BY YEAR
B16: Year | C16: 2026-27 | D16: 2027-28 | E16: 2028-29 | F16: 2029-30 | G16: 2030-31 | H16: 2031-32 | I16: Basis
B17: Fee per student (₹) | C17: =$C$6*(1+$C$7) -> 42046.858 | D17: =C17*(1+$C$7) -> 44990.138 | E17: =D17*(1+$C$7) -> 48139.448 | F17: =E17*(1+$C$7) -> 51509.209 | G17: =F17*(1+$C$7) -> 55114.854 | H17: =G17*(1+$C$7) -> 58972.894 | I17: Compounded from the FY26 actual
B19: STUDENT NUMBERS — THREE CASES
B20: Case | C20: 2026-27 | D20: 2027-28 | E20: 2028-29 | F20: 2029-30 | G20: 2030-31 | H20: 2031-32 | I20: Rationale
B21: A — Organic (no new capital) | C21: 190 | D21: 215 | E21: 245 | F21: 280 | G21: 320 | H21: 360 | I21: What the school can reach on its own cash, without the ₹2 Cr. This is the pre-money case.
B22: B — Management Conservative | C22: 200 | D22: 250 | E22: 310 | F22: 370 | G22: 460 | H22: 540 | I22: Management’s own conservative trajectory, which assumes the raise is received.
B23: C — Management Moderate | C23: 200 | D23: 275 | E23: 375 | F23: 485 | G23: 605 | H23: 705 | I23: Management’s moderate trajectory, which also assumes a third preschool feeding in.
B25: Historical students, Nagre Nagar | C25: 2018-19: 60 | D25: 2019-20: 104 | E25: 2020-21: 45 | F25: 2021-22: 55 | G25: 2022-23: 90 | H25: 2023-24: 120 | I25: 2024-25: 145 · 2025-26: 155 · source Student-Growth sheet
B27: COST STRUCTURE
B28: Line | C28: 2026-27 | D28: 2027-28 | E28: 2028-29 | F28: 2029-30 | G28: 2030-31 | H28: 2031-32 | I28: Basis
B29: Staff cost, % of revenue | C29: 0.26 | D29: 0.28 | E29: 0.31 | F29: 0.34 | G29: 0.37 | H29: 0.39 | I29: Audited FY26 was 16.5% — a preschool with low-paid assistants. Ramps toward normal school levels as Grades 1-6 are added and qualified teachers are needed.
B30: Other operating cost, % of revenue | C30: 0.32 | D30: 0.31 | E30: 0.3 | F30: 0.29 | G30: 0.28 | H30: 0.27 | I30: Audited FY26 was 32.9% excluding rent, loan and stamp-duty items. Declines modestly with scale.
B31: Rent (₹) | C31: =$C$12 -> 1200000 | D31: =C31*(1+$C$13) -> 1260000 | E31: =D31*(1+$C$13) -> 1323000 | F31: =E31*(1+$C$13) -> 1389150 | G31: =F31*(1+$C$13) -> 1458607.5 | H31: =G31*(1+$C$13) -> 1531537.9 | I31: Reconciliation needed — see Open Questions, item 2
B32: Depreciation and amortisation (₹) | C32: 700000 | D32: 710000 | E32: 710000 | F32: 710000 | G32: 510000 | H32: 510000 | I32: ₹1.46 Cr building over 30 years once complete, plus stamp duty amortisation to FY30

Sheet Projections
B2: PROJECTIONS — THREE CASES
B3: Rebuilt from the audited FY26 base. Unlike the management model, these include tax.
B5: CASE A — ORGANIC (NO NEW CAPITAL)
B6: ₹ | C6: 2026-27 | D6: 2027-28 | E6: 2028-29 | F6: 2029-30 | G6: 2030-31 | H6: 2031-32
B7: Students | C7: ='Assumptions'!C21 -> 190 | D7: ='Assumptions'!D21 -> 215 | E7: ='Assumptions'!E21 -> 245 | F7: ='Assumptions'!F21 -> 280 | G7: ='Assumptions'!G21 -> 320 | H7: ='Assumptions'!H21 -> 360
B8: Fee per student (₹) | C8: ='Assumptions'!C17 -> 42046.858 | D8: ='Assumptions'!D17 -> 44990.138 | E8: ='Assumptions'!E17 -> 48139.448 | F8: ='Assumptions'!F17 -> 51509.209 | G8: ='Assumptions'!G17 -> 55114.854 | H8: ='Assumptions'!H17 -> 58972.894
B9: Revenue | C9: =C7*C8 -> 7988903 | D9: =D7*D8 -> 9672879.7 | E9: =E7*E8 -> 11794165 | F9: =F7*F8 -> 14422579 | G9: =G7*G8 -> 17636753 | H9: =H7*H8 -> 21230242
B10: Revenue growth | C10: — | D10: =D9/C9-1 -> 0.21078947 | E10: =E9/D9-1 -> 0.21930233 | F10: =F9/E9-1 -> 0.22285714 | G10: =G9/F9-1 -> 0.22285714 | H10: =H9/G9-1 -> 0.20375
B11: Staff cost | C11: =-C9*'Assumptions'!C29 -> -2077114.8 | D11: =-D9*'Assumptions'!D29 -> -2708406.3 | E11: =-E9*'Assumptions'!E29 -> -3656191.1 | F11: =-F9*'Assumptions'!F29 -> -4903676.7 | G11: =-G9*'Assumptions'!G29 -> -6525598.7 | H11: =-H9*'Assumptions'!H29 -> -8279794.3
B12: Rent | C12: =-'Assumptions'!C31 -> -1200000 | D12: =-'Assumptions'!D31 -> -1260000 | E12: =-'Assumptions'!E31 -> -1323000 | F12: =-'Assumptions'!F31 -> -1389150 | G12: =-'Assumptions'!G31 -> -1458607.5 | H12: =-'Assumptions'!H31 -> -1531537.9
B13: Other operating costs | C13: =-C9*'Assumptions'!C30 -> -2556449 | D13: =-D9*'Assumptions'!D30 -> -2998592.7 | E13: =-E9*'Assumptions'!E30 -> -3538249.4 | F13: =-F9*'Assumptions'!F30 -> -4182547.8 | G13: =-G9*'Assumptions'!G30 -> -4938290.9 | H13: =-H9*'Assumptions'!H30 -> -5732165.3
B14: EBITDA | C14: =SUM(C9:C13) -> 2155339.3 | D14: =SUM(D9:D13) -> 2705880.7 | E14: =SUM(E9:E13) -> 3276724.2 | F14: =SUM(F9:F13) -> 3947204.1 | G14: =SUM(G9:G13) -> 4714256.1 | H14: =SUM(H9:H13) -> 5686744.3
B15: EBITDA margin | C15: =C14/C9 -> 0.26979164 | D15: =D14/D9 -> 0.27973889 | E15: =E14/E9 -> 0.27782588 | F15: =F14/F9 -> 0.27368227 | G15: =G14/G9 -> 0.26729728 | H15: =H14/H9 -> 0.26786055
B16: Depreciation and amortisation | C16: =-'Assumptions'!C32 -> -700000 | D16: =-'Assumptions'!D32 -> -710000 | E16: =-'Assumptions'!E32 -> -710000 | F16: =-'Assumptions'!F32 -> -710000 | G16: =-'Assumptions'!G32 -> -510000 | H16: =-'Assumptions'!H32 -> -510000
B17: EBIT | C17: =C14+C16 -> 1455339.3 | D17: =D14+D16 -> 1995880.7 | E17: =E14+E16 -> 2566724.2 | F17: =F14+F16 -> 3237204.1 | G17: =G14+G16 -> 4204256.1 | H17: =H14+H16 -> 5176744.3
B18: Tax on EBIT | C18: =-C17*'Assumptions'!$C$8 -> -378388.21 | D18: =-D17*'Assumptions'!$C$8 -> -518928.98 | E18: =-E17*'Assumptions'!$C$8 -> -667348.3 | F18: =-F17*'Assumptions'!$C$8 -> -841673.06 | G18: =-G17*'Assumptions'!$C$8 -> -1093106.6 | H18: =-H17*'Assumptions'!$C$8 -> -1345953.5
B19: NOPAT | C19: =C17+C18 -> 1076951.1 | D19: =D17+D18 -> 1476951.7 | E19: =E17+E18 -> 1899375.9 | F19: =F17+F18 -> 2395531 | G19: =G17+G18 -> 3111149.5 | H19: =H17+H18 -> 3830790.8
B20: Add back depreciation | C20: =-C16 -> 700000 | D20: =-D16 -> 710000 | E20: =-E16 -> 710000 | F20: =-F16 -> 710000 | G20: =-G16 -> 510000 | H20: =-H16 -> 510000
B21: Maintenance capex | C21: =-C9*'Assumptions'!$C$11 -> -319556.12 | D21: =-D9*'Assumptions'!$C$11 -> -386915.19 | E21: =-E9*'Assumptions'!$C$11 -> -471766.59 | F21: =-F9*'Assumptions'!$C$11 -> -576903.14 | G21: =-G9*'Assumptions'!$C$11 -> -705470.13 | H21: =-H9*'Assumptions'!$C$11 -> -849209.67
B22: FREE CASH FLOW | C22: =C19+C20+C21 -> 1457394.9 | D22: =D19+D20+D21 -> 1800036.5 | E22: =E19+E20+E21 -> 2137609.3 | F22: =F19+F20+F21 -> 2528627.9 | G22: =G19+G20+G21 -> 2915679.4 | H22: =H19+H20+H21 -> 3491581.1
B24: CASE B — MANAGEMENT CONSERVATIVE
B25: ₹ | C25: 2026-27 | D25: 2027-28 | E25: 2028-29 | F25: 2029-30 | G25: 2030-31 | H25: 2031-32
B26: Students | C26: ='Assumptions'!C22 -> 200 | D26: ='Assumptions'!D22 -> 250 | E26: ='Assumptions'!E22 -> 310 | F26: ='Assumptions'!F22 -> 370 | G26: ='Assumptions'!G22 -> 460 | H26: ='Assumptions'!H22 -> 540
B27: Fee per student (₹) | C27: ='Assumptions'!C17 -> 42046.858 | D27: ='Assumptions'!D17 -> 44990.138 | E27: ='Assumptions'!E17 -> 48139.448 | F27: ='Assumptions'!F17 -> 51509.209 | G27: ='Assumptions'!G17 -> 55114.854 | H27: ='Assumptions'!H17 -> 58972.894
B28: Revenue | C28: =C26*C27 -> 8409371.6 | D28: =D26*D27 -> 11247535 | E28: =E26*E27 -> 14923229 | F28: =F26*F27 -> 19058407 | G28: =G26*G27 -> 25352833 | H28: =H26*H27 -> 31845363
B29: Revenue growth | C29: — | D29: =D28/C28-1 -> 0.3375 | E29: =E28/D28-1 -> 0.3268 | F29: =F28/E28-1 -> 0.27709677 | G29: =G28/F28-1 -> 0.33027027 | H29: =H28/G28-1 -> 0.25608696
B30: Staff cost | C30: =-C28*'Assumptions'!C29 -> -2186436.6 | D30: =-D28*'Assumptions'!D29 -> -3149309.7 | E30: =-E28*'Assumptions'!E29 -> -4626200.9 | F30: =-F28*'Assumptions'!F29 -> -6479858.5 | G30: =-G28*'Assumptions'!G29 -> -9380548.1 | H30: =-H28*'Assumptions'!H29 -> -12419691
B31: Rent | C31: =-'Assumptions'!C31 -> -1200000 | D31: =-'Assumptions'!D31 -> -1260000 | E31: =-'Assumptions'!E31 -> -1323000 | F31: =-'Assumptions'!F31 -> -1389150 | G31: =-'Assumptions'!G31 -> -1458607.5 | H31: =-'Assumptions'!H31 -> -1531537.9
B32: Other operating costs | C32: =-C28*'Assumptions'!C30 -> -2690998.9 | D32: =-D28*'Assumptions'!D30 -> -3486735.7 | E32: =-E28*'Assumptions'!E30 -> -4476968.6 | F32: =-F28*'Assumptions'!F30 -> -5526938.1 | G32: =-G28*'Assumptions'!G30 -> -7098793.2 | H32: =-H28*'Assumptions'!H30 -> -8598247.9
B33: EBITDA | C33: =SUM(C28:C32) -> 2331936.1 | D33: =SUM(D28:D32) -> 3351489.2 | E33: =SUM(E28:E32) -> 4497059.2 | F33: =SUM(F28:F32) -> 5662460.7 | G33: =SUM(G28:G32) -> 7414884 | H33: =SUM(H28:H32) -> 9295885.4
B34: EBITDA margin | C34: =C33/C28 -> 0.27730206 | D34: =D33/D28 -> 0.29797545 | E34: =E33/E28 -> 0.30134626 | F34: =F33/F28 -> 0.29711091 | G34: =G33/G28 -> 0.29246767 | H34: =H33/H28 -> 0.29190704
B35: Depreciation and amortisation | C35: =-'Assumptions'!C32 -> -700000 | D35: =-'Assumptions'!D32 -> -710000 | E35: =-'Assumptions'!E32 -> -710000 | F35: =-'Assumptions'!F32 -> -710000 | G35: =-'Assumptions'!G32 -> -510000 | H35: =-'Assumptions'!H32 -> -510000
B36: EBIT | C36: =C33+C35 -> 1631936.1 | D36: =D33+D35 -> 2641489.2 | E36: =E33+E35 -> 3787059.2 | F36: =F33+F35 -> 4952460.7 | G36: =G33+G35 -> 6904884 | H36: =H33+H35 -> 8785885.4
B37: Tax on EBIT | C37: =-C36*'Assumptions'!$C$8 -> -424303.38 | D37: =-D36*'Assumptions'!$C$8 -> -686787.18 | E37: =-E36*'Assumptions'!$C$8 -> -984635.4 | F37: =-F36*'Assumptions'!$C$8 -> -1287639.8 | G37: =-G36*'Assumptions'!$C$8 -> -1795269.8 | H37: =-H36*'Assumptions'!$C$8 -> -2284330.2
B38: NOPAT | C38: =C36+C37 -> 1207632.7 | D38: =D36+D37 -> 1954702 | E38: =E36+E37 -> 2802423.8 | F38: =F36+F37 -> 3664820.9 | G38: =G36+G37 -> 5109614.1 | H38: =H36+H37 -> 6501555.2
B39: Add back depreciation | C39: =-C35 -> 700000 | D39: =-D35 -> 710000 | E39: =-E35 -> 710000 | F39: =-F35 -> 710000 | G39: =-G35 -> 510000 | H39: =-H35 -> 510000
B40: Maintenance capex | C40: =-C28*'Assumptions'!$C$11 -> -336374.86 | D40: =-D28*'Assumptions'!$C$11 -> -449901.38 | E40: =-E28*'Assumptions'!$C$11 -> -596929.15 | F40: =-F28*'Assumptions'!$C$11 -> -762336.3 | G40: =-G28*'Assumptions'!$C$11 -> -1014113.3 | H40: =-H28*'Assumptions'!$C$11 -> -1273814.5
B41: FREE CASH FLOW | C41: =C38+C39+C40 -> 1571257.8 | D41: =D38+D39+D40 -> 2214800.6 | E41: =E38+E39+E40 -> 2915494.7 | F41: =F38+F39+F40 -> 3612484.6 | G41: =G38+G39+G40 -> 4605500.8 | H41: =H38+H39+H40 -> 5737740.7
B43: CASE C — MANAGEMENT MODERATE
B44: ₹ | C44: 2026-27 | D44: 2027-28 | E44: 2028-29 | F44: 2029-30 | G44: 2030-31 | H44: 2031-32
...

Sheet DCF
B2: DISCOUNTED CASH FLOW
B3: Enterprise value less net debt gives equity value.
B5: DISCOUNT RATE BUILD-UP
B6: Risk-free rate (10-year G-sec) | C6: 0.0675 | I6: Indicative
B7: Equity risk premium, India | C7: 0.075 | I7: Market
B8: Beta, education sector | C8: 0.9 | I8: Unlevered, sector
B9: Size and illiquidity premium | C9: 0.08 | I9: Unlisted, single site, no market for the shares
B10: Company-specific risk premium | C10: 0.04 | I10: One campus, leased land, Board permission not yet obtained, key-person dependence
B11: Cost of equity | C11: 0.235 | I11: Risk-free + beta × ERP + premiums
B12: Pre-tax cost of debt | C12: 0.1 | I12: Rate on existing loans per Raw-Data sheet
B13: After-tax cost of debt | C13: 0.074 | I13: × (1 − tax rate)
B14: Target equity weighting | C14: 0.7 | I14: Post-transaction
B15: WACC — rounded and used throughout | C15: 0.19 | I15: Entered on the Assumptions tab
B17: CASE A — ORGANIC (NO NEW CAPITAL)
B18: ₹ | C18: 2026-27 | D18: 2027-28 | E18: 2028-29 | F18: 2029-30 | G18: 2030-31 | H18: 2031-32 | I18: Total
B19: Free cash flow | C19: =Projections!C22 -> 1457394.9 | D19: =Projections!D22 -> 1800036.5 | E19: =Projections!E22 -> 2137609.3 | F19: =Projections!F22 -> 2528627.9 | G19: =Projections!G22 -> 2915679.4 | H19: =Projections!H22 -> 3491581.1
B20: Discount factor | C20: =1/(1+Assumptions!$C$9)^1 -> 0.84033613 | D20: =1/(1+Assumptions!$C$9)^2 -> 0.70616482 | E20: =1/(1+Assumptions!$C$9)^3 -> 0.59341581 | F20: =1/(1+Assumptions!$C$9)^4 -> 0.49866875 | G20: =1/(1+Assumptions!$C$9)^5 -> 0.41904937 | H20: =1/(1+Assumptions!$C$9)^6 -> 0.35214233
B21: Present value of cash flow | C21: =C19*C20 -> 1224701.6 | D21: =D19*D20 -> 1271122.5 | E21: =E19*E20 -> 1268491.2 | F21: =F19*F20 -> 1260947.7 | G21: =G19*G20 -> 1221813.6 | H21: =H19*H20 -> 1229533.5 | I21: =SUM(C21:H21) -> 7476610.1
B22: Terminal value at end of FY32 | C22: =H19*(1+Assumptions!$C$10)/(Assumptions!$C$9-Assumptions!$C$10) -> 26186858 | I22: Gordon growth
B23: Present value of terminal value | C23: =C22*H20 -> 9221501.3 | I23: =C23 -> 9221501.3
B24: ENTERPRISE VALUE | I24: =$I$21+$I$23 -> 16698111
B25: Less net debt | I25: =-'Audited Base'!$C$37 -> -13881206
B26: EQUITY VALUE | I26: =$I$24-'Audited Base'!$C$37 -> 2816905.4
B27: Terminal value as % of enterprise value | I27: =$I$23/$I$24 -> 0.55224816
B29: CASE B — MANAGEMENT CONSERVATIVE
B30: ₹ | C30: 2026-27 | D30: 2027-28 | E30: 2028-29 | F30: 2029-30 | G30: 2030-31 | H30: 2031-32 | I30: Total
B31: Free cash flow | C31: =Projections!C41 -> 1571257.8 | D31: =Projections!D41 -> 2214800.6 | E31: =Projections!E41 -> 2915494.7 | F31: =Projections!F41 -> 3612484.6 | G31: =Projections!G41 -> 4605500.8 | H31: =Projections!H41 -> 5737740.7
B32: Discount factor | C32: =1/(1+Assumptions!$C$9)^1 -> 0.84033613 | D32: =1/(1+Assumptions!$C$9)^2 -> 0.70616482 | E32: =1/(1+Assumptions!$C$9)^3 -> 0.59341581 | F32: =1/(1+Assumptions!$C$9)^4 -> 0.49866875 | G32: =1/(1+Assumptions!$C$9)^5 -> 0.41904937 | H32: =1/(1+Assumptions!$C$9)^6 -> 0.35214233
B33: Present value of cash flow | C33: =C31*C32 -> 1320384.7 | D33: =D31*D32 -> 1564014.3 | E33: =E31*E32 -> 1730100.7 | F33: =F31*F32 -> 1801433.2 | G33: =G31*G32 -> 1929932.2 | H33: =H31*H32 -> 2020501.4 | I33: =SUM(C33:H33) -> 10366366
B34: Terminal value at end of FY32 | C34: =H31*(1+Assumptions!$C$10)/(Assumptions!$C$9-Assumptions!$C$10) -> 43033055 | I34: Gordon growth
B35: Present value of terminal value | C35: =C34*H32 -> 15153760 | I35: =C35 -> 15153760
B36: ENTERPRISE VALUE | I36: =$I$33+$I$35 -> 25520127
B37: Less net debt | I37: =-'Audited Base'!$C$37 -> -13881206
B38: EQUITY VALUE | I38: =$I$36-'Audited Base'!$C$37 -> 11638921
B39: Terminal value as % of enterprise value | I39: =$I$35/$I$36 -> 0.59379643
B41: CASE C — MANAGEMENT MODERATE
B42: ₹ | C42: 2026-27 | D42: 2027-28 | E42: 2028-29 | F42: 2029-30 | G42: 2030-31 | H42: 2031-32 | I42: Total
B43: Free cash flow | C43: =Projections!C60 -> 1571257.8 | D43: =Projections!D60 -> 2511060.7 | E43: =Projections!E60 -> 3693380 | F43: =Projections!F60 -> 4997412.8 | G43: =Projections!G60 -> 6355673 | H43: =Projections!H60 -> 7796720.3
B44: Discount factor | C44: =1/(1+Assumptions!$C$9)^1 -> 0.84033613 | D44: =1/(1+Assumptions!$C$9)^2 -> 0.70616482 | E44: =1/(1+Assumptions!$C$9)^3 -> 0.59341581 | F44: =1/(1+Assumptions!$C$9)^4 -> 0.49866875 | G44: =1/(1+Assumptions!$C$9)^5 -> 0.41904937 | H44: =1/(1+Assumptions!$C$9)^6 -> 0.35214233
B45: Present value of cash flow | C45: =C43*C44 -> 1320384.7 | D45: =D43*D44 -> 1773222.7 | E45: =E43*E44 -> 2191710.1 | F45: =F43*F44 -> 2492053.6 | G45: =G43*G44 -> 2663340.8 | H45: =H43*H44 -> 2745555.2 | I45: =SUM(C45:H45) -> 13186267
...

Sheet Multiples & NAV
B2: MARKET MULTIPLES AND NET ASSET VALUE
B3: Cross-checks on the DCF, applied to audited FY26 figures.
B5: REVENUE MULTIPLE
B6: Multiple | C6: Enterprise value | D6: Less net debt | E6: Equity value | F6: Comment
B7: 2 | C7: =B7*'Audited Base'!$C$7 -> 12181800 | D7: =-'Audited Base'!$C$37 -> -13881206 | E7: =C7+D7 -> -1699406 | F7: Distressed / asset-backed
B8: 3 | C8: =B8*'Audited Base'!$C$7 -> 18272700 | D8: =-'Audited Base'!$C$37 -> -13881206 | E8: =C8+D8 -> 4391494 | F8: Small single-site school
B9: 4 | C9: =B9*'Audited Base'!$C$7 -> 24363600 | D9: =-'Audited Base'!$C$37 -> -13881206 | E9: =C9+D9 -> 10482394 | F9: Strong growth, established
B10: 5 | C10: =B10*'Audited Base'!$C$7 -> 30454500 | D10: =-'Audited Base'!$C$37 -> -13881206 | E10: =C10+D10 -> 16573294 | F10: Top of any defensible range
B11: 16.4 | C11: =B11*'Audited Base'!$C$7 -> 99890760 | D11: =-'Audited Base'!$C$37 -> -13881206 | E11: =C11+D11 -> 86009554 | F11: Implied by the ₹10 crore expectation
B13: EBITDA MULTIPLE
B14: Multiple | C14: Enterprise value | D14: Less net debt | E14: Equity value | F14: Comment
B15: 8 | C15: =B15*'Audited Base'!$C$25 -> 18193760 | D15: =-'Audited Base'!$C$37 -> -13881206 | E15: =C15+D15 -> 4312554 | F15: Small, illiquid, single asset
B16: 10 | C16: =B16*'Audited Base'!$C$25 -> 22742200 | D16: =-'Audited Base'!$C$37 -> -13881206 | E16: =C16+D16 -> 8860994 | F16: Mid-point
B17: 12 | C17: =B17*'Audited Base'!$C$25 -> 27290640 | D17: =-'Audited Base'!$C$37 -> -13881206 | E17: =C17+D17 -> 13409434 | F17: Growth premium
B18: 15 | C18: =B18*'Audited Base'!$C$25 -> 34113300 | D18: =-'Audited Base'!$C$37 -> -13881206 | E18: =C18+D18 -> 20232094 | F18: Top of any defensible range
B19: 50.1 | C19: =B19*'Audited Base'!$C$25 -> 113938422 | D19: =-'Audited Base'!$C$37 -> -13881206 | E19: =C19+D19 -> 100057216 | F19: Implied by the ₹10 crore expectation
B21: NET ASSET VALUE — THE FLOOR
B22: Book equity per audited balance sheet | C22: ='Audited Base'!$C$32 -> 1318945 | F22: Land is leased, so there is no land value to add
B23: Per share (6,000 shares) | C23: ='Audited Base'!$C$32/6000 -> 219.82417 | F23: Management report states ₹31 per share
B25: The building was constructed with borrowed money, so its value is already offset by the debt that funded it. That is why equity value is thin despite ₹1.50 crore of property on the balance sheet: the lenders rank ahead of the shareholders.

Sheet Reverse Test
B2: REVERSE TEST — WHAT WOULD HAVE TO BE TRUE FOR ₹10 CRORE
B3: Working backwards from the valuation the client expects, to the assumptions it requires.
B5: THE TARGET
B6: Expected valuation (₹10 lakh per 1%) | C6: 100000000
B7: Add net debt to reach the required enterprise value | C7: ='Audited Base'!$C$37 -> 13881206
B8: Required enterprise value | C8: =$C$6+C7 -> 113881206
B10: ROUTE 1 — HOLD THE MODERATE CASE, SOLVE FOR THE DISCOUNT RATE
B11: WACC applied to Case C | C11: Equity value | D11: vs ₹10 crore target
B12: 0.1 | C12: 96580029 | D12: =C12/$C$6 -> 0.96580029 | E12: ← reaches the target
B13: 0.11 | C13: 76452909 | D13: =C13/$C$6 -> 0.76452909
B14: 0.12 | C14: 62135684 | D14: =C14/$C$6 -> 0.62135684
B15: 0.14 | C15: 43175028 | D15: =C15/$C$6 -> 0.43175028
B16: 0.19 | C16: 19896725 | D16: =C16/$C$6 -> 0.19896725
B18: A 10% discount rate is what you would apply to a listed infrastructure utility with contracted cash flows. The school pays 10% on its own secured bank borrowings. Using 10% as the cost of EQUITY asserts that a minority stake in a single unlisted school, on leased land, without Maharashtra Board permission, carries no more risk than the bank loan secured against it. No investor will accept that.
B20: ROUTE 2 — HOLD THE DISCOUNT RATE, SOLVE FOR SCALE
B21: Enterprise value produced by the Moderate case | C21: 33777931
B22: Required enterprise value | C22: 113881206
B23: Scale-up factor required | C23: 3.3714677 | F23: Applied to the whole Moderate case
B24: Implied FY32 revenue | C24: 1.4017177e+08 | F24: vs ₹4.16 crore in the Moderate case
B25: Implied FY32 student count | C25: 2376.8848 | F25: vs 705 Moderate, 920 Bullish, 155 today
B27: Reaching ₹10 crore at a defensible discount rate requires roughly 2,377 students by FY32 — about 2.6 times the most bullish case management has put forward, and 15 times the current roll of 155. The campus is 8,500 sq ft.
B29: WHAT THE ₹10 CRORE EXPECTATION IMPLIES ON TODAY’S NUMBERS
B30: Metric | C30: Audited FY26 | D30: Implied multiple at ₹10 crore
B31: Revenue | C31: ='Audited Base'!$C$7 -> 6090900 | D31: =$C$6/C31 -> 16.417935
B32: Adjusted EBITDA | C32: ='Audited Base'!$C$25 -> 2274220 | D32: =$C$6/C32 -> 43.97112
B33: Profit after tax | C33: 1258940 | D33: =$C$6/C33 -> 79.431903
B34: Book equity | C34: ='Audited Base'!$C$32 -> 1318945 | D34: =$C$6/C34 -> 75.818173

Sheet Open Questions
B2: OPEN QUESTIONS
B3: Each of these could move the conclusion. They are listed in order of impact.
B5: # | C5: Question | D5: Why it matters to the valuation
B6: 1 | C6: Is FY 2025-26 a full twelve months? The company was incorporated during that year and all prior-year figures are nil. | D6: If it is a part year, the real run-rate revenue is higher than ₹60.91 lakh and every multiple-based value rises with it. Revenue per student of ₹39,297 is close to the ₹37,500 management uses, which suggests a full academic year — but this needs confirming. HIGHEST-IMPACT UNKNOWN.
B7: 2 | C7: Why does projected rent jump from ₹8.04 lakh audited to ₹20.40 lakh? | D7: A ₹12 lakh annual cost difference. If the higher figure is right, EBITDA in every projection year falls by that amount.
B8: 3 | C8: Why is projected staff cost ₹28.08 lakh against ₹10.08 lakh audited, for a similar roll? | D8: Adding Grades 1-6 requires qualified teachers at higher pay, so a rise is expected — but 2.8x needs explaining. It is the single largest cost line.
B9: 4 | C9: Who lent the ₹1.62 crore shown as unsecured borrowings? | D9: If the promoters on-lent personally borrowed money to fund the building, the loan-repayment use of proceeds is far more defensible than it first appears, and should be presented that way.
B10: 5 | C10: Do the projections cover Nagre Nagar alone, or both campuses? | D10: The Notes state the investor acquires an interest in Nagre Nagar only, with Govind Nagar remaining standalone. If the projections consolidate both, revenue is overstated for what is being sold.
B11: 6 | C11: What are the terms of the land lease — lessor, tenure, assignment, change of control, right to create a charge? | D11: Determines whether the ₹1.46 crore building can be charged as security, whether a change of control is permitted, and whether there is any residual asset value.
B12: 7 | C12: What is the physical capacity of the 8,500 sq ft campus? | D12: Management projects 540 to 920 students. If capacity is materially below that, the projections are not achievable without further construction and further capital.
B13: 8 | C13: Confirm the entity is a Section 8 company, and what instrument can lawfully be offered. | D13: Determines whether equity can pay a return at all. Until this is settled, we do not know what asset we are valuing. Check MCA master data against the CIN.
B14: 9 | C14: Is there any 12AB registration or exemption claimed? | D14: The company paid tax at 29% in FY26 with no exemption claimed, which may be an oversight worth several lakh a year and would lift the value.
B16: This workbook is a preliminary commercial valuation prepared for the adviser’s internal use and for discussion with management. It is not a valuation report under Section 247 of the Companies Act, 2013, and the preparer is not an IBBI-registered valuer. It is not legal, secretarial or tax advice.
